<?xml version="1.0"?>
<!-- ======================================================================== -->
<!-- | Flexiv Rizon 10 (with blurred dynamic parameters)                    | -->
<!-- ======================================================================== -->
<robot name="rizon10">
  <joint name="joint1" type="revolute">
    <parent link="base_link" />
    <child link="link1" />
    <origin rpy="0.0 0.0 -3.141592653589793" xyz="0.0 0.0 0.21" />
    <axis xyz="0 0 1" />
    <limit effort="261" lower="-2.7925" upper="2.7925" velocity="1.7453" />
  </joint>
  <joint name="joint2" type="revolute">
    <parent link="link1" />
    <child link="link2" />
    <origin rpy="0.0 0.0 0.0" xyz="0.0 0.0675 0.24" />
    <axis xyz="0 1 0" />
    <limit effort="261" lower="-2.6704" upper="2.6704" velocity="1.7453" />
  </joint>
  <joint name="joint3" type="revolute">
    <parent link="link2" />
    <child link="link3" />
    <origin rpy="0.0 0.0 0.0" xyz="0.0 0.0625 0.2275" />
    <axis xyz="0 0 1" />
    <limit effort="123" lower="-2.7925" upper="2.7925" velocity="2.0944" />
  </joint>
  <joint name="joint4" type="revolute">
    <parent link="link3" />
    <child link="link4" />
    <origin rpy="0.0 0.0 -3.141592653589793" xyz="0.0 -0.0625 0.2225" />
    <axis xyz="0 1 0" />
    <limit effort="123" lower="-2.7053" upper="2.7053" velocity="2.0944" />
  </joint>
  <joint name="joint5" type="revolute">
    <parent link="link4" />
    <child link="link5" />
    <origin rpy="0.0 0.0 -3.141592653589793" xyz="0.0 0.0575 0.205" />
    <axis xyz="0 0 1" />
    <limit effort="57" lower="-2.9671" upper="2.9671" velocity="3.8397" />
  </joint>
  <joint name="joint6" type="revolute">
    <parent link="link5" />
    <child link="link6" />
    <origin rpy="0.0 0.0 0.0" xyz="0.0 0.03 0.19" />
    <axis xyz="0 1 0" />
    <limit effort="57" lower="-1.3963" upper="4.5379" velocity="3.8397" />
  </joint>
  <joint name="joint7" type="revolute">
    <parent link="link6" />
    <child link="link7" />
    <origin rpy="0.0 -1.5707963478683205 0.0" xyz="-0.015 0.073 0.11" />
    <axis xyz="0 0 1" />
    <limit effort="57" lower="-2.9671" upper="2.9671" velocity="3.8397" />
  </joint>
  <joint name="link7_to_flange" type="fixed">
    <parent link="link7" />
    <child link="flange" />
    <origin rpy="0.0 0.0 -3.141592653589793" xyz="0.0 0.0 0.081" />
  </joint>

  <link name="base_link">
    <inertial>
      <mass value="9.2" />
      <origin rpy="0 0 0" xyz="0.0 -0.0 0.13" />
      <inertia ixx="0.08" ixy="0.0" ixz="-0.0" iyy="0.08" iyz="0.0" izz="0.04" />
    </inertial>
    <visual>
      <origin rpy="0 0 0" xyz="0 0 0" />
      <geometry>
        <mesh filename="meshes/rizon10/visual/link0.obj" />
      </geometry>
      <material name="rizon_dark_grey" />
    </visual>
    <collision>
      <origin rpy="0 0 0" xyz="0 0 0" />
      <geometry>
        <mesh filename="meshes/rizon10/collision/link0.stl" />
      </geometry>
    </collision>
  </link>
  <link name="link1">
    <inertial>
      <mass value="9.7" />
      <origin rpy="0 0 0" xyz="0.0 0.03 0.16" />
      <inertia ixx="0.18" ixy="0.0" ixz="0.0" iyy="0.17" iyz="0.02" izz="0.04" />
    </inertial>
    <visual>
      <origin rpy="0 0 0" xyz="0 0 0" />
      <geometry>
        <mesh filename="meshes/rizon10/visual/link1.obj" />
      </geometry>
      <material name="rizon_dark_grey" />
    </visual>
    <collision>
      <origin rpy="0 0 0" xyz="0 0 0" />
      <geometry>
        <mesh filename="meshes/rizon10/collision/link1.stl" />
      </geometry>
    </collision>
  </link>
  <link name="link2">
    <inertial>
      <mass value="6.2" />
      <origin rpy="0 0 0" xyz="0.0 0.03 0.11" />
      <inertia ixx="0.1" ixy="0.0" ixz="0.0" iyy="0.08" iyz="0.02" izz="0.03" />
    </inertial>
    <visual>
      <origin rpy="0 0 0" xyz="0 0 0" />
      <geometry>
        <mesh filename="meshes/rizon10/visual/link2.obj" />
      </geometry>
      <material name="rizon_dark_grey" />
    </visual>
    <collision>
      <origin rpy="0 0 0" xyz="0 0 0" />
      <geometry>
        <mesh filename="meshes/rizon10/collision/link2.stl" />
      </geometry>
    </collision>
  </link>
  <link name="link3">
    <inertial>
      <mass value="4.6" />
      <origin rpy="0 0 0" xyz="0.0 -0.03 0.17" />
      <inertia ixx="0.04" ixy="-0.0" ixz="-0.0" iyy="0.03" iyz="-0.01" izz="0.01" />
    </inertial>
    <visual>
      <origin rpy="0 0 0" xyz="0 0 0" />
      <geometry>
        <mesh filename="meshes/rizon10/visual/link3.obj" />
      </geometry>
      <material name="rizon_dark_grey" />
    </visual>
    <collision>
      <origin rpy="0 0 0" xyz="0 0 0" />
      <geometry>
        <mesh filename="meshes/rizon10/collision/link3.stl" />
      </geometry>
    </collision>
  </link>
  <link name="link4">
    <inertial>
      <mass value="3.0" />
      <origin rpy="0 0 0" xyz="-0.0 0.05 0.1" />
      <inertia ixx="0.03" ixy="0.0" ixz="-0.0" iyy="0.03" iyz="0.0" izz="0.0" />
    </inertial>
    <visual>
      <origin rpy="0 0 0" xyz="0 0 0" />
      <geometry>
        <mesh filename="meshes/rizon10/visual/link4.obj" />
      </geometry>
      <material name="rizon_dark_grey" />
    </visual>
    <collision>
      <origin rpy="0 0 0" xyz="0 0 0" />
      <geometry>
        <mesh filename="meshes/rizon10/collision/link4.stl" />
      </geometry>
    </collision>
  </link>
  <link name="link5">
    <inertial>
      <mass value="2.4" />
      <origin rpy="0 0 0" xyz="0.0 0.01 0.13" />
      <inertia ixx="0.01" ixy="0.0" ixz="0.0" iyy="0.01" iyz="0.0" izz="0.0" />
    </inertial>
    <visual>
      <origin rpy="0 0 0" xyz="0 0 0" />
      <geometry>
        <mesh filename="meshes/rizon10/visual/link5.obj" />
      </geometry>
      <material name="rizon_dark_grey" />
    </visual>
    <collision>
      <origin rpy="0 0 0" xyz="0 0 0" />
      <geometry>
        <mesh filename="meshes/rizon10/collision/link5.stl" />
      </geometry>
    </collision>
  </link>
  <link name="link6">
    <inertial>
      <mass value="2.3" />
      <origin rpy="0 0 0" xyz="0.02 0.06 0.07" />
      <inertia ixx="0.01" ixy="0.0" ixz="0.0" iyy="0.01" iyz="0.0" izz="0.0" />
    </inertial>
    <visual>
      <origin rpy="0 0 0" xyz="0 0 0" />
      <geometry>
        <mesh filename="meshes/rizon10/visual/link6.obj" />
      </geometry>
      <material name="rizon_dark_grey" />
    </visual>
    <collision>
      <origin rpy="0 0 0" xyz="0 0 0" />
      <geometry>
        <mesh filename="meshes/rizon10/collision/link6.stl" />
      </geometry>
    </collision>
  </link>
  <link name="link7">
    <inertial>
      <mass value="0.9" />
      <origin rpy="0 0 0" xyz="0.0 -0.0 0.03" />
      <inertia ixx="0.0" ixy="0.0" ixz="0.0" iyy="0.0" iyz="0.0" izz="0.0" />
    </inertial>
    <visual>
      <origin rpy="0 0 0" xyz="0 0 0" />
      <geometry>
        <mesh filename="meshes/rizon10/visual/link7.obj" />
      </geometry>
      <material name="rizon_dark_grey" />
    </visual>
    <collision>
      <origin rpy="0 0 0" xyz="0 0 0" />
      <geometry>
        <mesh filename="meshes/rizon10/collision/link7.stl" />
      </geometry>
    </collision>
  </link>
  <link name="flange" />
  <material name="rizon_blue">
    <color rgba="0.0 0.0 1.0 0.5" />
  </material>
  <material name="rizon_light_grey">
    <color rgba="0.7 0.7 0.7 1.0" />
  </material>
  <material name="rizon_dark_grey">
    <color rgba="0.4 0.4 0.4 1.0" />
  </material>
  <material name="rizon_white">
    <color rgba="1.0 1.0 1.0 1.0" />
  </material>
</robot>