<?xml version="1.0"?>
<!-- ======================================================================== -->
<!-- | Flexiv Rizon4 Arm (with approximated dynamic parameters)             | -->
<!-- ======================================================================== -->
<robot name="A02L_MP">
  
  <joint name="joint0" type="fixed">
    <origin rpy="0 0 0" xyz="0 0.5 0" />
    <parent link="world" />
    <child link="base_link" />
  </joint>
  <joint name="joint0_1" type="fixed">
    <origin rpy="0 0 0" xyz="0 -0.5 0" />
    <parent link="world" />
    <child link="base_link_1" />
  </joint>



  <joint name="joint1" type="revolute">
    <parent link="base_link" />
    <child link="link1" />
    <origin rpy="0 0 3.141592653589793" xyz="0.0 0.0 0.155" />
    <axis xyz="0 0 1" />
    <limit effort="123" lower="-2.58" upper="2.58" velocity="2.0944" />
  </joint>
  <joint name="joint2" type="revolute">
    <parent link="link1" />
    <child link="link2" />
    <origin rpy="0 0 0" xyz="0.0 0.03 0.210" />
    <axis xyz="0 1 0" />
    <limit effort="123" lower="-2.05" upper="2.05" velocity="2.0944" />
  </joint>
  <joint name="joint3" type="revolute">
    <parent link="link2" />
    <child link="link3" />
    <origin rpy="0 0 0" xyz="0.0 0.035 0.205" />
    <axis xyz="0 0 1" />
    <limit effort="64" lower="-2.75" upper="2.75" velocity="2.4435" />
  </joint>
  <joint name="joint4" type="revolute">
    <parent link="link3" />
    <child link="link4" />
    <origin rpy="0 0 -3.141592653589793" xyz="-0.02 -0.03 0.19" />
    <axis xyz="0 1 0" />
    <limit effort="64" lower="-1.64" upper="2.47" velocity="2.4435" />
  </joint>
  <joint name="joint5" type="revolute">
    <parent link="link4" />
    <child link="link5" />
    <origin rpy="0 0 -3.141592653589793" xyz="-0.02 0.025 0.195" />
    <axis xyz="0 0 1" />
    <limit effort="39" lower="-2.77" upper="2.77" velocity="4.8869" />
  </joint>
  <joint name="joint6" type="revolute">
    <parent link="link5" />
    <child link="link6" />
    <origin rpy="0 0 0" xyz="0.0 0.03 0.19" />
    <axis xyz="0 1 0" />
    <limit effort="39" lower="-1.21" upper="4.35" velocity="4.8869" />
  </joint>
  <joint name="joint7" type="revolute">
    <parent link="link6" />
    <child link="link7" />
    <origin rpy="0 -1.5707963267948966 0" xyz="-0.055 0.070 0.11" />
    <axis xyz="0 0 1" />
    <limit effort="39" lower="-2.77" upper="2.77" velocity="4.8869" />
  </joint>
  
  <joint name="link7_to_flange" type="fixed">
    <parent link="link7" />
    <child link="flange" />
    <origin rpy="0 0 -3.141592653589793" xyz="0.0 0.0 0.081" />
  </joint>



  <joint name="joint1_1" type="revolute">
    <parent link="base_link_1" />
    <child link="link1_1" />
    <origin rpy="0 0 3.141592653589793" xyz="0.0 0.0 0.155" />
    <axis xyz="0 0 1" />
    <limit effort="123" lower="-2.58" upper="2.58" velocity="2.0944" />
  </joint>
  <joint name="joint2_1" type="revolute">
    <parent link="link1_1" />
    <child link="link2_1" />
    <origin rpy="0 0 0" xyz="0.0 0.03 0.210" />
    <axis xyz="0 1 0" />
    <limit effort="123" lower="-2.05" upper="2.05" velocity="2.0944" />
  </joint>
  <joint name="joint3_1" type="revolute">
    <parent link="link2_1" />
    <child link="link3_1" />
    <origin rpy="0 0 0" xyz="0.0 0.035 0.205" />
    <axis xyz="0 0 1" />
    <limit effort="64" lower="-2.75" upper="2.75" velocity="2.4435" />
  </joint>
  <joint name="joint4_1" type="revolute">
    <parent link="link3_1" />
    <child link="link4_1" />
    <origin rpy="0 0 -3.141592653589793" xyz="-0.02 -0.03 0.19" />
    <axis xyz="0 1 0" />
    <limit effort="64" lower="-1.64" upper="2.47" velocity="2.4435" />
  </joint>
  <joint name="joint5_1" type="revolute">
    <parent link="link4_1" />
    <child link="link5_1" />
    <origin rpy="0 0 -3.141592653589793" xyz="-0.02 0.025 0.195" />
    <axis xyz="0 0 1" />
    <limit effort="39" lower="-2.77" upper="2.77" velocity="4.8869" />
  </joint>
  <joint name="joint6_1" type="revolute">
    <parent link="link5_1" />
    <child link="link6_1" />
    <origin rpy="0 0 0" xyz="0.0 0.03 0.19" />
    <axis xyz="0 1 0" />
    <limit effort="39" lower="-1.21" upper="4.35" velocity="4.8869" />
  </joint>
  <joint name="joint7_1" type="revolute">
    <parent link="link6_1" />
    <child link="link7_1" />
    <origin rpy="0 -1.5707963267948966 0" xyz="-0.055 0.070 0.11" />
    <axis xyz="0 0 1" />
    <limit effort="39" lower="-2.77" upper="2.77" velocity="4.8869" />
  </joint>
  
  <joint name="link7_to_flange_1" type="fixed">
    <parent link="link7_1" />
    <child link="flange_1" />
    <origin rpy="0 0 -3.141592653589793" xyz="0.0 0.0 0.081" />
  </joint>


  

  <link name="world" />
  <link name="base_link">
    <inertial>
      <mass value="3.7" />
      <origin rpy="0 0 0" xyz="0.0 -0.0 0.09" />
      <inertia ixx="0.019" ixy="0.0" ixz="0.0" iyy="0.02" iyz="0.0" izz="0.009" />
    </inertial>
    <visual>
      <origin rpy="0 0 0" xyz="0 0 0" />
      <geometry>
        <mesh filename="meshes/visual/link0.stl" />
      </geometry>
      <material name="rizon_light_grey" />
    </visual>
    <collision>
      <origin rpy="0 0 0" xyz="0 0 0" />
      <geometry>
        <mesh filename="meshes/collision/link0.stl" />
      </geometry>
    </collision>
  </link>
  <link name="link1">
    <inertial>
      <mass value="3.7" />
      <origin rpy="0 0 0" xyz="0.0 0.01 0.15" />
      <inertia ixx="0.028" ixy="0.0" ixz="0.0" iyy="0.027" iyz="0.002" izz="0.008" />
    </inertial>
    <visual>
      <origin rpy="0 0 0" xyz="0 0 0" />
      <geometry>
        <mesh filename="meshes/visual/link1.stl" />
      </geometry>
      <material name="rizon_light_grey" />
    </visual>
    <collision>
      <origin rpy="0 0 0" xyz="0 0 0" />
      <geometry>
        <mesh filename="meshes/collision/link1.stl" />
      </geometry>
    </collision>
  </link>
  <link name="link2">
    <inertial>
      <mass value="2.7" />
      <origin rpy="0 0 0" xyz="0.0 0.04 0.1" />
      <inertia ixx="0.023" ixy="0.0" ixz="0.0" iyy="0.024" iyz="-0.0" izz="0.004" />
    </inertial>
    <visual>
      <origin rpy="0 0 0" xyz="0 0 0" />
      <geometry>
        <mesh filename="meshes/visual/link2.stl" />
      </geometry>
      <material name="rizon_light_grey" />
    </visual>
    <collision>
      <origin rpy="0 0 0" xyz="0 0 0" />
      <geometry>
        <mesh filename="meshes/collision/link2.stl" />
      </geometry>
    </collision>
  </link>
  <link name="link3">
    <inertial>
      <mass value="2.4" />
      <origin rpy="0 0 0" xyz="-0.01 -0.0 0.13" />
      <inertia ixx="0.014" ixy="0.0" ixz="-0.001" iyy="0.014" iyz="-0.001" izz="0.004" />
    </inertial>
    <visual>
      <origin rpy="0 0 0" xyz="0 0 0" />
      <geometry>
        <mesh filename="meshes/visual/link3.stl" />
      </geometry>
      <material name="rizon_light_grey" />
    </visual>
    <collision>
      <origin rpy="0 0 0" xyz="0 0 0" />
      <geometry>
        <mesh filename="meshes/collision/link3.stl" />
      </geometry>
    </collision>
  </link>
  <link name="link4">
    <inertial>
      <mass value="2.4" />
      <origin rpy="0 0 0" xyz="-0.01 0.03 0.1" />
      <inertia ixx="0.018" ixy="0.0" ixz="-0.002" iyy="0.019" iyz="-0.001" izz="0.003" />
    </inertial>
    <visual>
      <origin rpy="0 0 0" xyz="0 0 0" />
      <geometry>
        <mesh filename="meshes/visual/link4.stl" />
      </geometry>
      <material name="rizon_light_grey" />
    </visual>
    <collision>
      <origin rpy="0 0 0" xyz="0 0 0" />
      <geometry>
        <mesh filename="meshes/collision/link4.stl" />
      </geometry>
    </collision>
  </link>
  <link name="link5">
    <inertial>
      <mass value="2.4" />
      <origin rpy="0 0 0" xyz="0.0 0.0 0.13" />
      <inertia ixx="0.014" ixy="0.0" ixz="0.0" iyy="0.013" iyz="0.001" izz="0.004" />
    </inertial>
    <visual>
      <origin rpy="0 0 0" xyz="0 0 0" />
      <geometry>
        <mesh filename="meshes/visual/link5.stl" />
      </geometry>
      <material name="rizon_light_grey" />
    </visual>
    <collision>
      <origin rpy="0 0 0" xyz="0 0 0" />
      <geometry>
        <mesh filename="meshes/collision/link5.stl" />
      </geometry>
    </collision>
  </link>
  <link name="link6">
    <inertial>
      <mass value="2.1" />
      <origin rpy="0 0 0" xyz="-0.01 0.06 0.07" />
      <inertia ixx="0.008" ixy="-0.0" ixz="-0.001" iyy="0.009" iyz="0.002" izz="0.004" />
    </inertial>
    <visual>
      <origin rpy="0 0 0" xyz="0 0 0" />
      <geometry>
        <mesh filename="meshes/visual/link6.stl" />
      </geometry>
      <material name="rizon_light_grey" />
    </visual>
    <collision>
      <origin rpy="0 0 0" xyz="0 0 0" />
      <geometry>
        <mesh filename="meshes/collision/link6.stl" />
      </geometry>
    </collision>
  </link>
  <link name="link7">
    <inertial>
      <mass value="0.8" />
      <origin rpy="0 0 0" xyz="0.0 0.0 0.03" />
      <inertia ixx="0.001" ixy="0.0" ixz="0.0" iyy="0.001" iyz="0.0" izz="0.001" />
    </inertial>
    <visual>
      <origin rpy="0 0 0" xyz="0 0 0" />
      <geometry>
        <mesh filename="meshes/visual/link7.stl" />
      </geometry>
      <material name="rizon_light_grey" />
    </visual>
    <collision>
      <origin rpy="0 0 0" xyz="0 0 0" />
      <geometry>
        <mesh filename="meshes/collision/link7.stl" />
      </geometry>
    </collision>
  </link>
  
  <link name="flange" />






  <link name="base_link_1">
    <inertial>
      <mass value="3.7" />
      <origin rpy="0 0 0" xyz="0.0 -0.0 0.09" />
      <inertia ixx="0.019" ixy="0.0" ixz="0.0" iyy="0.02" iyz="0.0" izz="0.009" />
    </inertial>
    <visual>
      <origin rpy="0 0 0" xyz="0 0 0" />
      <geometry>
        <mesh filename="meshes/visual/link0.stl" />
      </geometry>
      <material name="rizon_light_grey" />
    </visual>
    <collision>
      <origin rpy="0 0 0" xyz="0 0 0" />
      <geometry>
        <mesh filename="meshes/collision/link0.stl" />
      </geometry>
    </collision>
  </link>
  <link name="link1_1">
    <inertial>
      <mass value="3.7" />
      <origin rpy="0 0 0" xyz="0.0 0.01 0.15" />
      <inertia ixx="0.028" ixy="0.0" ixz="0.0" iyy="0.027" iyz="0.002" izz="0.008" />
    </inertial>
    <visual>
      <origin rpy="0 0 0" xyz="0 0 0" />
      <geometry>
        <mesh filename="meshes/visual/link1.stl" />
      </geometry>
      <material name="rizon_light_grey" />
    </visual>
    <collision>
      <origin rpy="0 0 0" xyz="0 0 0" />
      <geometry>
        <mesh filename="meshes/collision/link1.stl" />
      </geometry>
    </collision>
  </link>
  <link name="link2_1">
    <inertial>
      <mass value="2.7" />
      <origin rpy="0 0 0" xyz="0.0 0.04 0.1" />
      <inertia ixx="0.023" ixy="0.0" ixz="0.0" iyy="0.024" iyz="-0.0" izz="0.004" />
    </inertial>
    <visual>
      <origin rpy="0 0 0" xyz="0 0 0" />
      <geometry>
        <mesh filename="meshes/visual/link2.stl" />
      </geometry>
      <material name="rizon_light_grey" />
    </visual>
    <collision>
      <origin rpy="0 0 0" xyz="0 0 0" />
      <geometry>
        <mesh filename="meshes/collision/link2.stl" />
      </geometry>
    </collision>
  </link>
  <link name="link3_1">
    <inertial>
      <mass value="2.4" />
      <origin rpy="0 0 0" xyz="-0.01 -0.0 0.13" />
      <inertia ixx="0.014" ixy="0.0" ixz="-0.001" iyy="0.014" iyz="-0.001" izz="0.004" />
    </inertial>
    <visual>
      <origin rpy="0 0 0" xyz="0 0 0" />
      <geometry>
        <mesh filename="meshes/visual/link3.stl" />
      </geometry>
      <material name="rizon_light_grey" />
    </visual>
    <collision>
      <origin rpy="0 0 0" xyz="0 0 0" />
      <geometry>
        <mesh filename="meshes/collision/link3.stl" />
      </geometry>
    </collision>
  </link>
  <link name="link4_1">
    <inertial>
      <mass value="2.4" />
      <origin rpy="0 0 0" xyz="-0.01 0.03 0.1" />
      <inertia ixx="0.018" ixy="0.0" ixz="-0.002" iyy="0.019" iyz="-0.001" izz="0.003" />
    </inertial>
    <visual>
      <origin rpy="0 0 0" xyz="0 0 0" />
      <geometry>
        <mesh filename="meshes/visual/link4.stl" />
      </geometry>
      <material name="rizon_light_grey" />
    </visual>
    <collision>
      <origin rpy="0 0 0" xyz="0 0 0" />
      <geometry>
        <mesh filename="meshes/collision/link4.stl" />
      </geometry>
    </collision>
  </link>
  <link name="link5_1">
    <inertial>
      <mass value="2.4" />
      <origin rpy="0 0 0" xyz="0.0 0.0 0.13" />
      <inertia ixx="0.014" ixy="0.0" ixz="0.0" iyy="0.013" iyz="0.001" izz="0.004" />
    </inertial>
    <visual>
      <origin rpy="0 0 0" xyz="0 0 0" />
      <geometry>
        <mesh filename="meshes/visual/link5.stl" />
      </geometry>
      <material name="rizon_light_grey" />
    </visual>
    <collision>
      <origin rpy="0 0 0" xyz="0 0 0" />
      <geometry>
        <mesh filename="meshes/collision/link5.stl" />
      </geometry>
    </collision>
  </link>
  <link name="link6_1">
    <inertial>
      <mass value="2.1" />
      <origin rpy="0 0 0" xyz="-0.01 0.06 0.07" />
      <inertia ixx="0.008" ixy="-0.0" ixz="-0.001" iyy="0.009" iyz="0.002" izz="0.004" />
    </inertial>
    <visual>
      <origin rpy="0 0 0" xyz="0 0 0" />
      <geometry>
        <mesh filename="meshes/visual/link6.stl" />
      </geometry>
      <material name="rizon_light_grey" />
    </visual>
    <collision>
      <origin rpy="0 0 0" xyz="0 0 0" />
      <geometry>
        <mesh filename="meshes/collision/link6.stl" />
      </geometry>
    </collision>
  </link>
  <link name="link7_1">
    <inertial>
      <mass value="0.8" />
      <origin rpy="0 0 0" xyz="0.0 0.0 0.03" />
      <inertia ixx="0.001" ixy="0.0" ixz="0.0" iyy="0.001" iyz="0.0" izz="0.001" />
    </inertial>
    <visual>
      <origin rpy="0 0 0" xyz="0 0 0" />
      <geometry>
        <mesh filename="meshes/visual/link7.stl" />
      </geometry>
      <material name="rizon_light_grey" />
    </visual>
    <collision>
      <origin rpy="0 0 0" xyz="0 0 0" />
      <geometry>
        <mesh filename="meshes/collision/link7.stl" />
      </geometry>
    </collision>
  </link>
  
  <link name="flange_1" />


<!--=====================================================================-->
  


  <joint name="flange_ee_fixed" type="fixed">
        <origin rpy="0 0 0" xyz="0 0 0.17" />
        <parent link="flange" />
        <child link="ee_target" />
  </joint>
<link name="ee_target" />

  <joint name="flange_ee_fixed_1" type="fixed">
        <origin rpy="0 0 0" xyz="0 0 0.17" />
        <parent link="flange_1" />
        <child link="ee_target_1" />
  </joint>
<link name="ee_target_1" />


<!--=====================================================================-->


<joint name="flange_fixed" type="fixed">
        <origin rpy="0 0 1.5707" xyz="0 0 0" />
        <parent link="flange" />
        <child link="rightgripper_base_link" />
  </joint>
  
  <link name="rightgripper_base_link">
	<visual>
	    <geometry>
		<mesh filename="meshes/dhag95/visual/base_link_0001.stl" />
	    </geometry>
	</visual>
	<collision>
	    <geometry>
		<mesh filename="meshes/dhag95/visual/base_link_0001.stl" />
	    </geometry>
	</collision>
	<inertial>
	    <mass value="0.83416" />
	    <origin xyz="0.0 0.0 0.0" rpy="0 0 0" />
	    <inertia ixx="0.0013016" ixy="-0.0000007" ixz="0.0000006" iyx="0.000000" iyy="0.00049972" iyz="0.0000002" izx="0.000000" izy="0.000000" izz="0.001498" />
	</inertial>
	</link>


<joint name="rightgripper_finger1_inner_knuckle_joint" type="continuous">
	<parent link="rightgripper_base_link" />
	<child link="rightgripper_finger1_inner_knuckle_link" />
	<axis xyz="0 1 0" />
	<origin rpy="0.0 0.0 3.141592653589793" xyz="-0.016 0 0.10586" />
	<limit effort="0.1" lower="-3.14" upper="3.14" velocity="3.0" />

	</joint>
	<joint name="rightgripper_finger2_inner_knuckle_joint" type="continuous">
	<parent link="rightgripper_base_link" />
	<child link="rightgripper_finger2_inner_knuckle_link" />
	<axis xyz="0 1 0" />
	<origin rpy="0.0 0.0 0.0" xyz="0.016 0 0.10586" />
	<limit effort="0.1" lower="-3.14" upper="3.14" velocity="3.0" />

	</joint>
	<link name="rightgripper_finger1_inner_knuckle_link">
	<visual>
	    <geometry>
		<mesh filename="meshes/dhag95/visual/proximal_phalanx_Link_0001.stl" />
	    </geometry>
	</visual>
	<collision>
	    <geometry>
		<mesh filename="meshes/dhag95/visual/proximal_phalanx_Link_0001.stl" />
	    </geometry>
	</collision>
	<inertial>
	    <mass value="0.0318004" />
	    <origin xyz="0.0 0.0 0.0" rpy="0 0 0" />
	    <inertia ixx="0.000014" ixy="0.0" ixz="-0.000005" iyx="0.000000" iyy="0.00001" iyz="0.0" izx="0.000000" izy="0.000000" izz="0.0000136" />
	</inertial>
	</link>

	<link name="rightgripper_finger2_inner_knuckle_link">
	<visual>
	    <geometry>
		<mesh filename="meshes/dhag95/visual/proximal_phalanx_Link_0001.stl" />
	    </geometry>
	</visual>
	<collision>
	    <geometry>
		<mesh filename="meshes/dhag95/visual/proximal_phalanx_Link_0001.stl" />
	    </geometry>
	</collision>
	<inertial>
	    <mass value="0.0318004" />
	    <origin xyz="0.0 0.0 0.0" rpy="0 0 0" />
	    <inertia ixx="0.000014" ixy="0.0" ixz="-0.000005" iyx="0.000000" iyy="0.00001" iyz="0.0" izx="0.000000" izy="0.000000" izz="0.0000136" />
	</inertial>
	</link>

	<joint name="rightgripper_finger1_finger_tip_joint" type="continuous">
	<parent link="rightgripper_finger1_inner_knuckle_link" />
	<child link="rightgripper_finger1_finger_tip_link" />
	<axis xyz="0 1 0" />
	<origin rpy="0.0 0.0 0.0" xyz="0.0394969463769 0.0 0.0382752038125 " />
	<limit effort="0.1" lower="-3.14" upper="3.14" velocity="3.0" />

	</joint>
	<joint name="rightgripper_finger2_finger_tip_joint" type="continuous">
	<parent link="rightgripper_finger2_inner_knuckle_link" />
	<child link="rightgripper_finger2_finger_tip_link" />
	<axis xyz="0 1 0" />
	<origin rpy="0.0 0.0 0.0" xyz="0.0394969463769  0.0 0.0382752038125  " />
	<limit effort="0.1" lower="-3.14" upper="3.14" velocity="3.0" />

	</joint>
	<link name="rightgripper_finger1_finger_tip_link">
	<visual>
	    <geometry>
		<mesh filename="meshes/dhag95/visual/distal_phalanx_Link_0001.stl" />
	    </geometry>
	</visual>
	<collision>
	    <geometry>
		<mesh filename="meshes/dhag95/visual/distal_phalanx_Link_0001.stl" />
	    </geometry>
	</collision>
	<inertial>
	    <mass value="0.0124305" />
	    <origin xyz="0.0 0.0 0.0" rpy="0 0 0" />
	    <inertia ixx="0.0000028" ixy="0.0" ixz="0.0000008" iyx="0.000000" iyy="0.000003" iyz="2.16427e-13" izx="0.000000" izy="0.000000" izz="0.0000011" />
	</inertial>
	</link>
	<link name="rightgripper_finger2_finger_tip_link">
	<visual>
	    <geometry>
		<mesh filename="meshes/dhag95/visual/distal_phalanx_Link_0001.stl" />
	    </geometry>
	</visual>
	<collision>
	    <geometry>
		<mesh filename="meshes/dhag95/visual/distal_phalanx_Link_0001.stl" />
	    </geometry>
	</collision>
	<inertial>
	    <mass value="0.0124305" />
	    <origin xyz="0.0 0.0 0.0" rpy="0 0 0" />
	    <inertia ixx="0.0000028" ixy="0.0" ixz="0.0000008" iyx="0.000000" iyy="0.000003" iyz="2.16427e-13" izx="0.000000" izy="0.000000" izz="0.0000011" />
	</inertial>
	</link>

<!--====================================================-->


  <joint name="flange_fixed_1" type="fixed">
        <origin rpy="0 0 1.5707" xyz="0 0 0" />
        <parent link="flange_1" />
        <child link="rightgripper_base_link_1" />
  </joint>
  
  <link name="rightgripper_base_link_1">
	<visual>
	    <geometry>
		<mesh filename="meshes/dhag95/visual/base_link_0001.stl" />
	    </geometry>
	</visual>
	<collision>
	    <geometry>
		<mesh filename="meshes/dhag95/visual/base_link_0001.stl" />
	    </geometry>
	</collision>
	<inertial>
	    <mass value="0.83416" />
	    <origin xyz="0.0 0.0 0.0" rpy="0 0 0" />
	    <inertia ixx="0.0013016" ixy="-0.0000007" ixz="0.0000006" iyx="0.000000" iyy="0.00049972" iyz="0.0000002" izx="0.000000" izy="0.000000" izz="0.001498" />
	</inertial>
	</link>


<joint name="rightgripper_finger1_inner_knuckle_joint_1" type="continuous">
	<parent link="rightgripper_base_link_1" />
	<child link="rightgripper_finger1_inner_knuckle_link_1" />
	<axis xyz="0 1 0" />
	<origin rpy="0.0 0.0 3.141592653589793" xyz="-0.016 0 0.10586" />
	<limit effort="0.1" lower="-3.14" upper="3.14" velocity="3.0" />

	</joint>
	<joint name="rightgripper_finger2_inner_knuckle_joint_1" type="continuous">
	<parent link="rightgripper_base_link_1" />
	<child link="rightgripper_finger2_inner_knuckle_link_1" />
	<axis xyz="0 1 0" />
	<origin rpy="0.0 0.0 0.0" xyz="0.016 0 0.10586" />
	<limit effort="0.1" lower="-3.14" upper="3.14" velocity="3.0" />

	</joint>
	<link name="rightgripper_finger1_inner_knuckle_link_1">
	<visual>
	    <geometry>
		<mesh filename="meshes/dhag95/visual/proximal_phalanx_Link_0001.stl" />
	    </geometry>
	</visual>
	<collision>
	    <geometry>
		<mesh filename="meshes/dhag95/visual/proximal_phalanx_Link_0001.stl" />
	    </geometry>
	</collision>
	<inertial>
	    <mass value="0.0318004" />
	    <origin xyz="0.0 0.0 0.0" rpy="0 0 0" />
	    <inertia ixx="0.000014" ixy="0.0" ixz="-0.000005" iyx="0.000000" iyy="0.00001" iyz="0.0" izx="0.000000" izy="0.000000" izz="0.0000136" />
	</inertial>
	</link>

	<link name="rightgripper_finger2_inner_knuckle_link_1">
	<visual>
	    <geometry>
		<mesh filename="meshes/dhag95/visual/proximal_phalanx_Link_0001.stl" />
	    </geometry>
	</visual>
	<collision>
	    <geometry>
		<mesh filename="meshes/dhag95/visual/proximal_phalanx_Link_0001.stl" />
	    </geometry>
	</collision>
	<inertial>
	    <mass value="0.0318004" />
	    <origin xyz="0.0 0.0 0.0" rpy="0 0 0" />
	    <inertia ixx="0.000014" ixy="0.0" ixz="-0.000005" iyx="0.000000" iyy="0.00001" iyz="0.0" izx="0.000000" izy="0.000000" izz="0.0000136" />
	</inertial>
	</link>

	<joint name="rightgripper_finger1_finger_tip_joint_1" type="continuous">
	<parent link="rightgripper_finger1_inner_knuckle_link_1" />
	<child link="rightgripper_finger1_finger_tip_link_1" />
	<axis xyz="0 1 0" />
	<origin rpy="0.0 0.0 0.0" xyz="0.0394969463769 0.0 0.0382752038125 " />
	<limit effort="0.1" lower="-3.14" upper="3.14" velocity="3.0" />

	</joint>
	<joint name="rightgripper_finger2_finger_tip_joint_1" type="continuous">
	<parent link="rightgripper_finger2_inner_knuckle_link_1" />
	<child link="rightgripper_finger2_finger_tip_link_1" />
	<axis xyz="0 1 0" />
	<origin rpy="0.0 0.0 0.0" xyz="0.0394969463769  0.0 0.0382752038125  " />
	<limit effort="0.1" lower="-3.14" upper="3.14" velocity="3.0" />

	</joint>
	<link name="rightgripper_finger1_finger_tip_link_1">
	<visual>
	    <geometry>
		<mesh filename="meshes/dhag95/visual/distal_phalanx_Link_0001.stl" />
	    </geometry>
	</visual>
	<collision>
	    <geometry>
		<mesh filename="meshes/dhag95/visual/distal_phalanx_Link_0001.stl" />
	    </geometry>
	</collision>
	<inertial>
	    <mass value="0.0124305" />
	    <origin xyz="0.0 0.0 0.0" rpy="0 0 0" />
	    <inertia ixx="0.0000028" ixy="0.0" ixz="0.0000008" iyx="0.000000" iyy="0.000003" iyz="2.16427e-13" izx="0.000000" izy="0.000000" izz="0.0000011" />
	</inertial>
	</link>
	<link name="rightgripper_finger2_finger_tip_link_1">
	<visual>
	    <geometry>
		<mesh filename="meshes/dhag95/visual/distal_phalanx_Link_0001.stl" />
	    </geometry>
	</visual>
	<collision>
	    <geometry>
		<mesh filename="meshes/dhag95/visual/distal_phalanx_Link_0001.stl" />
	    </geometry>
	</collision>
	<inertial>
	    <mass value="0.0124305" />
	    <origin xyz="0.0 0.0 0.0" rpy="0 0 0" />
	    <inertia ixx="0.0000028" ixy="0.0" ixz="0.0000008" iyx="0.000000" iyy="0.000003" iyz="2.16427e-13" izx="0.000000" izy="0.000000" izz="0.0000011" />
	</inertial>
	</link>



</robot>
