<?xml version="1.0" ?>
<!-- =================================================================================== -->
<!-- |    This document was autogenerated by xacro from srhand_ur.urdf.xacro           | -->
<!-- |    EDITING THIS FILE BY HAND IS NOT RECOMMENDED                                 | -->
<!-- =================================================================================== -->
<!--
 Software License Agreement (BSD License)
 Copyright © 2022-2023 belongs to Shadow Robot Company Ltd.
 All rights reserved.
 Redistribution and use in source and binary forms, with or without modification,
 are permitted provided that the following conditions are met:
   1. Redistributions of source code must retain the above copyright notice,
      this list of conditions and the following disclaimer.
   2. Redistributions in binary form must reproduce the above copyright notice,
      this list of conditions and the following disclaimer in the documentation
      and/or other materials provided with the distribution.
   3. Neither the name of Shadow Robot Company Ltd nor the names of its contributors
      may be used to endorse or promote products derived from this software without
      specific prior written permission.
 This software is provided by Shadow Robot Company Ltd "as is" and any express
 or implied warranties, including, but not limited to, the implied warranties of
 merchantability and fitness for a particular purpose are disclaimed. In no event
 shall the copyright holder be liable for any direct, indirect, incidental, special,
 exemplary, or consequential damages (including, but not limited to, procurement of
 substitute goods or services; loss of use, data, or profits; or business interruption)
 however caused and on any theory of liability, whether in contract, strict liability,
 or tort (including negligence or otherwise) arising in any way out of the use of this
 software, even if advised of the possibility of such damage.
-->
<robot name="sr_hand_ur10e_right" xmlns:controller="http://playerstage.sourceforge.net/gazebo/xmlschema/#controller" xmlns:interface="http://playerstage.sourceforge.net/gazebo/xmlschema/#interface" xmlns:sensor="http://playerstage.sourceforge.net/gazebo/xmlschema/#sensor">
  <link name="world"/>
  <!--
    Base UR robot series xacro macro.

    NOTE: this is NOT a URDF. It cannot directly be loaded by consumers
    expecting a flattened '.urdf' file. See the top-level '.xacro' for that
    (but note: that .xacro must still be processed by the xacro command).

    For use in '.launch' files: use one of the 'load_urX.launch' convenience
    launch files.

    This file models the base kinematic chain of a UR robot, which then gets
    parameterised by various configuration files to convert it into a UR3(e),
    UR5(e), UR10(e) or UR16e.

    NOTE: the default kinematic parameters (ie: link lengths, frame locations,
    offets, etc) do not correspond to any particular robot. They are defaults
    only. There WILL be non-zero offsets between the Forward Kinematics results
    in TF (ie: robot_state_publisher) and the values reported by the Teach
    Pendant.

    For accurate (and robot-specific) transforms, the 'kinematics_parameters_file'
    parameter MUST point to a .yaml file containing the appropriate values for
    the targetted robot.

    If using the UniversalRobots/Universal_Robots_ROS_Driver, follow the steps
    described in the readme of that repository to extract the kinematic
    calibration from the controller and generate the required .yaml file.

    Main author of the migration to yaml configs: Ludovic Delval.

    Contributors to previous versions (in no particular order):

     - Felix Messmer
     - Kelsey Hawkins
     - Wim Meeussen
     - Shaun Edwards
     - Nadia Hammoudeh Garcia
     - Dave Hershberger
     - G. vd. Hoorn
     - Philip Long
     - Dave Coleman
     - Miguel Prada
     - Mathias Luedtke
     - Marcel Schnirring
     - Felix von Drigalski
     - Felix Exner
     - Jimmy Da Silva
     - Ajit Krisshna N L
     - Muhammad Asif Rana
  -->
  <!--
    NOTE: the macro defined in this file is NOT part of the public API of this
          package. Users CANNOT rely on this file being available, or stored in
          this location. Nor can they rely on the existence of the macro.
  -->
  <transmission name="ra_shoulder_pan_trans">
    <type>transmission_interface/SimpleTransmission</type>
    <joint name="ra_shoulder_pan_joint">
      <hardwareInterface>hardware_interface/PositionJointInterface</hardwareInterface>
    </joint>
    <actuator name="ra_shoulder_pan_motor">
      <mechanicalReduction>1</mechanicalReduction>
    </actuator>
  </transmission>
  <transmission name="ra_shoulder_lift_trans">
    <type>transmission_interface/SimpleTransmission</type>
    <joint name="ra_shoulder_lift_joint">
      <hardwareInterface>hardware_interface/PositionJointInterface</hardwareInterface>
    </joint>
    <actuator name="ra_shoulder_lift_motor">
      <mechanicalReduction>1</mechanicalReduction>
    </actuator>
  </transmission>
  <transmission name="ra_elbow_trans">
    <type>transmission_interface/SimpleTransmission</type>
    <joint name="ra_elbow_joint">
      <hardwareInterface>hardware_interface/PositionJointInterface</hardwareInterface>
    </joint>
    <actuator name="ra_elbow_motor">
      <mechanicalReduction>1</mechanicalReduction>
    </actuator>
  </transmission>
  <transmission name="ra_wrist_1_trans">
    <type>transmission_interface/SimpleTransmission</type>
    <joint name="ra_wrist_1_joint">
      <hardwareInterface>hardware_interface/PositionJointInterface</hardwareInterface>
    </joint>
    <actuator name="ra_wrist_1_motor">
      <mechanicalReduction>1</mechanicalReduction>
    </actuator>
  </transmission>
  <transmission name="ra_wrist_2_trans">
    <type>transmission_interface/SimpleTransmission</type>
    <joint name="ra_wrist_2_joint">
      <hardwareInterface>hardware_interface/PositionJointInterface</hardwareInterface>
    </joint>
    <actuator name="ra_wrist_2_motor">
      <mechanicalReduction>1</mechanicalReduction>
    </actuator>
  </transmission>
  <transmission name="ra_wrist_3_trans">
    <type>transmission_interface/SimpleTransmission</type>
    <joint name="ra_wrist_3_joint">
      <hardwareInterface>hardware_interface/PositionJointInterface</hardwareInterface>
    </joint>
    <actuator name="ra_wrist_3_motor">
      <mechanicalReduction>1</mechanicalReduction>
    </actuator>
  </transmission>
  <!-- links: main serial chain -->
  <link name="ra_base_link"/>
  <link name="ra_base_link_inertia">
    <visual>
      <origin rpy="0 0 3.141592653589793" xyz="0 0 0"/>
      <geometry>
        <mesh filename="meshes/ur10e/visual/base.dae"/>
      </geometry>
      <material name="LightGrey">
        <color rgba="0.7 0.7 0.7 1.0"/>
      </material>
    </visual>
    <collision>
      <origin rpy="0 0 3.141592653589793" xyz="0 0 0"/>
      <geometry>
        <mesh filename="meshes/ur10e/collision/base.stl"/>
      </geometry>
    </collision>
    <inertial>
      <mass value="4.0"/>
      <origin rpy="0 0 0" xyz="0 0 0"/>
      <inertia ixx="0.0061063308908" ixy="0.0" ixz="0.0" iyy="0.0061063308908" iyz="0.0" izz="0.01125"/>
    </inertial>
  </link>
  <link name="ra_shoulder_link">
    <visual>
      <origin rpy="0 0 3.141592653589793" xyz="0 0 0"/>
      <geometry>
        <mesh filename="meshes/ur10e/visual/shoulder.dae"/>
      </geometry>
      <material name="LightGrey">
        <color rgba="0.7 0.7 0.7 1.0"/>
      </material>
    </visual>
    <collision>
      <origin rpy="0 0 3.141592653589793" xyz="0 0 0"/>
      <geometry>
        <mesh filename="meshes/ur10e/collision/shoulder.stl"/>
      </geometry>
    </collision>
    <inertial>
      <mass value="7.778"/>
      <origin rpy="0 0 0" xyz="0 0 0"/>
      <inertia ixx="0.03147431257693659" ixy="0.0" ixz="0.0" iyy="0.03147431257693659" iyz="0.0" izz="0.021875624999999996"/>
    </inertial>
  </link>
  <link name="ra_upper_arm_link">
    <visual>
      <origin rpy="1.5707963267948966 0 -1.5707963267948966" xyz="0 0 0.1762"/>
      <geometry>
        <mesh filename="meshes/ur10e/visual/upperarm.dae"/>
      </geometry>
      <material name="LightGrey">
        <color rgba="0.7 0.7 0.7 1.0"/>
      </material>
    </visual>
    <collision>
      <origin rpy="1.5707963267948966 0 -1.5707963267948966" xyz="0 0 0.1762"/>
      <geometry>
        <mesh filename="meshes/ur10e/collision/upperarm.stl"/>
      </geometry>
    </collision>
    <inertial>
      <mass value="12.93"/>
      <origin rpy="0 1.5707963267948966 0" xyz="-0.306 0.0 0.175"/>
      <inertia ixx="0.42175380379841093" ixy="0.0" ixz="0.0" iyy="0.42175380379841093" iyz="0.0" izz="0.03636562499999999"/>
    </inertial>
  </link>
  <link name="ra_forearm_link">
    <visual>
      <origin rpy="1.5707963267948966 0 -1.5707963267948966" xyz="0 0 0.0393"/>
      <geometry>
        <mesh filename="meshes/ur10e/visual/forearm.dae"/>
      </geometry>
      <material name="LightGrey">
        <color rgba="0.7 0.7 0.7 1.0"/>
      </material>
    </visual>
    <collision>
      <origin rpy="1.5707963267948966 0 -1.5707963267948966" xyz="0 0 0.0393"/>
      <geometry>
        <mesh filename="meshes/ur10e/collision/forearm.stl"/>
      </geometry>
    </collision>
    <inertial>
      <mass value="3.87"/>
      <origin rpy="0 1.5707963267948966 0" xyz="-0.285775 0.0 0.0393"/>
      <inertia ixx="0.11079302548902206" ixy="0.0" ixz="0.0" iyy="0.11079302548902206" iyz="0.0" izz="0.010884375"/>
    </inertial>
  </link>
  <link name="ra_wrist_1_link">
    <visual>
      <!-- TODO: Move this to a parameter -->
      <origin rpy="1.5707963267948966 0 0" xyz="0 0 -0.135"/>
      <geometry>
        <mesh filename="meshes/ur10e/visual/wrist1.dae"/>
      </geometry>
      <material name="LightGrey">
        <color rgba="0.7 0.7 0.7 1.0"/>
      </material>
    </visual>
    <collision>
      <origin rpy="1.5707963267948966 0 0" xyz="0 0 -0.135"/>
      <geometry>
        <mesh filename="meshes/ur10e/collision/wrist1.stl"/>
      </geometry>
    </collision>
    <inertial>
      <mass value="1.96"/>
      <origin rpy="0 0 0" xyz="0 0 0"/>
      <inertia ixx="0.005108247956699999" ixy="0.0" ixz="0.0" iyy="0.005108247956699999" iyz="0.0" izz="0.005512499999999999"/>
    </inertial>
  </link>
  <link name="ra_wrist_2_link">
    <visual>
      <origin rpy="0 0 0" xyz="0 0 -0.12"/>
      <geometry>
        <mesh filename="meshes/ur10e/visual/wrist2.dae"/>
      </geometry>
      <material name="LightGrey">
        <color rgba="0.7 0.7 0.7 1.0"/>
      </material>
    </visual>
    <collision>
      <origin rpy="0 0 0" xyz="0 0 -0.12"/>
      <geometry>
        <mesh filename="meshes/ur10e/collision/wrist2.stl"/>
      </geometry>
    </collision>
    <inertial>
      <mass value="1.96"/>
      <origin rpy="0 0 0" xyz="0 0 0"/>
      <inertia ixx="0.005108247956699999" ixy="0.0" ixz="0.0" iyy="0.005108247956699999" iyz="0.0" izz="0.005512499999999999"/>
    </inertial>
  </link>
  <link name="ra_wrist_3_link">
    <visual>
      <origin rpy="1.5707963267948966 0 0" xyz="0 0 -0.1168"/>
      <geometry>
        <mesh filename="meshes/ur10e/visual/wrist3.dae"/>
      </geometry>
      <material name="LightGrey">
        <color rgba="0.7 0.7 0.7 1.0"/>
      </material>
    </visual>
    <collision>
      <origin rpy="1.5707963267948966 0 0" xyz="0 0 -0.1168"/>
      <geometry>
        <mesh filename="meshes/ur10e/collision/wrist3.stl"/>
      </geometry>
    </collision>
    <inertial>
      <mass value="0.202"/>
      <origin rpy="0 0 0" xyz="0.0 0.0 -0.025"/>
      <inertia ixx="0.00014434577559500002" ixy="0.0" ixz="0.0" iyy="0.00014434577559500002" iyz="0.0" izz="0.00020452500000000002"/>
    </inertial>
  </link>
  <!-- joints: main serial chain -->
  <joint name="ra_base_link-base_link_inertia" type="fixed">
    <parent link="ra_base_link"/>
    <child link="ra_base_link_inertia"/>
    <!-- 'base_link' is REP-103 aligned (so X+ forward), while the internal
           frames of the robot/controller have X+ pointing backwards.
           Use the joint between 'base_link' and 'base_link_inertia' (a dummy
           link/frame) to introduce the necessary rotation over Z (of pi rad).
      -->
    <origin rpy="0 0 3.141592653589793" xyz="0 0 0"/>
  </joint>
  <joint name="ra_shoulder_pan_joint" type="revolute">
    <parent link="ra_base_link_inertia"/>
    <child link="ra_shoulder_link"/>
    <origin rpy="0 0 0" xyz="0 0 0.1807"/>
    <axis xyz="0 0 1"/>
    <limit effort="330.0" lower="-6.283185307179586" upper="6.283185307179586" velocity="2.0943951023931953"/>
    <dynamics damping="0" friction="0"/>
  </joint>
  <joint name="ra_shoulder_lift_joint" type="revolute">
    <parent link="ra_shoulder_link"/>
    <child link="ra_upper_arm_link"/>
    <origin rpy="1.570796327 0 0" xyz="0 0 0"/>
    <axis xyz="0 0 1"/>
    <limit effort="330.0" lower="-6.283185307179586" upper="6.283185307179586" velocity="2.0943951023931953"/>
    <dynamics damping="0" friction="0"/>
  </joint>
  <joint name="ra_elbow_joint" type="revolute">
    <parent link="ra_upper_arm_link"/>
    <child link="ra_forearm_link"/>
    <origin rpy="0 0 0" xyz="-0.6127 0 0"/>
    <axis xyz="0 0 1"/>
    <limit effort="150.0" lower="-3.141592653589793" upper="3.141592653589793" velocity="3.141592653589793"/>
    <dynamics damping="0" friction="0"/>
  </joint>
  <joint name="ra_wrist_1_joint" type="revolute">
    <parent link="ra_forearm_link"/>
    <child link="ra_wrist_1_link"/>
    <origin rpy="0 0 0" xyz="-0.57155 0 0.17415"/>
    <axis xyz="0 0 1"/>
    <limit effort="56.0" lower="-6.283185307179586" upper="6.283185307179586" velocity="3.141592653589793"/>
    <dynamics damping="0" friction="0"/>
  </joint>
  <joint name="ra_wrist_2_joint" type="revolute">
    <parent link="ra_wrist_1_link"/>
    <child link="ra_wrist_2_link"/>
    <origin rpy="1.570796327 0 0" xyz="0 -0.11985 -2.458164590756244e-11"/>
    <axis xyz="0 0 1"/>
    <limit effort="56.0" lower="-6.283185307179586" upper="6.283185307179586" velocity="3.141592653589793"/>
    <dynamics damping="0" friction="0"/>
  </joint>
  <joint name="ra_wrist_3_joint" type="revolute">
    <parent link="ra_wrist_2_link"/>
    <child link="ra_wrist_3_link"/>
    <origin rpy="1.570796326589793 3.141592653589793 3.141592653589793" xyz="0 0.11655 -2.390480459346185e-11"/>
    <axis xyz="0 0 1"/>
    <limit effort="56.0" lower="-6.283185307179586" upper="6.283185307179586" velocity="3.141592653589793"/>
    <dynamics damping="0" friction="0"/>
  </joint>
  <!-- ROS-Industrial 'base' frame: base_link to UR 'Base' Coordinates transform -->
  <link name="ra_base"/>
  <joint name="ra_base_link-base_fixed_joint" type="fixed">
    <!-- Note the rotation over Z of pi radians: as base_link is REP-103
           aligned (ie: has X+ forward, Y+ left and Z+ up), this is needed
           to correctly align 'base' with the 'Base' coordinate system of
           the UR controller.
      -->
    <origin rpy="0 0 3.141592653589793" xyz="0 0 0"/>
    <parent link="ra_base_link"/>
    <child link="ra_base"/>
  </joint>
  <!-- ROS-Industrial 'flange' frame: attachment point for EEF models -->
  <link name="ra_flange"/>
  <joint name="ra_wrist_3-flange" type="fixed">
    <parent link="ra_wrist_3_link"/>
    <child link="ra_flange"/>
    <origin rpy="0 -1.5707963267948966 -1.5707963267948966" xyz="0 0 0"/>
  </joint>
  <!-- ROS-Industrial 'tool0' frame: all-zeros tool frame -->
  <link name="ra_tool0"/>
  <joint name="ra_flange-tool0" type="fixed">
    <!-- default toolframe: X+ left, Y+ up, Z+ front -->
    <origin rpy="1.5707963267948966 0 1.5707963267948966" xyz="0 0 0"/>
    <parent link="ra_flange"/>
    <child link="ra_tool0"/>
  </joint>
  <material name="Blue">
    <color rgba="0.0 0.0 0.8 1.0"/>
  </material>
  <material name="Green">
    <color rgba="0.0 0.8 0.0 1.0"/>
  </material>
  <material name="BiotacGreen">
    <color rgba="0.31 0.85 0.42 1.0"/>
  </material>
  <material name="Grey">
    <color rgba="0.2 0.2 0.2 1.0"/>
  </material>
  <material name="LightGrey">
    <color rgba="0.6 0.6 0.6 1.0"/>
  </material>
  <material name="Red">
    <color rgba="0.8 0.0 0.0 1.0"/>
  </material>
  <material name="White">
    <color rgba="1.0 1.0 1.0 1.0"/>
  </material>
  <gazebo>
    <plugin filename="libgazebo_ros_control.so" name="gazebo_ros_control">
      <robotSimType>sr_gazebo_sim/SrGazeboHWSim</robotSimType>
    </plugin>
  </gazebo>
  <link name="rh_forearm">
    <inertial>
      <origin rpy="0 0 0" xyz="0 0 0.09"/>
      <mass value="3.0"/>
      <inertia ixx="0.0138" ixy="0.0" ixz="0.0" iyy="0.0138" iyz="0.0" izz="0.00744"/>
    </inertial>
    <visual>
      <origin rpy="0 0 0" xyz="0 0 0.006"/>
      <geometry name="rh_forearm_visual">
        <mesh filename="meshes/sr_hand/components/forearm/forearm_E3M5.dae" scale="0.001 0.001 0.001"/>
      </geometry>
      <material name="light_grey">
        <color rgba="0.90000 0.90000 0.90000 1.0"/>
      </material>
    </visual>
    <collision>
      <origin rpy="0 0 0" xyz="0 0 0.006"/>
      <geometry name="rh_forearm_collision">
        <mesh filename="meshes/sr_hand/components/forearm/forearm_collision_E3M5.dae" scale="0.001 0.001 0.001"/>
      </geometry>
    </collision>
    <!-- wrist mount -->
    <collision>
      <origin rpy="0 0.78 0" xyz="0 -0.01 0.187"/>
      <geometry>
        <box size="0.07 0.07 0.07"/>
      </geometry>
    </collision>
    <visual>
      <origin rpy="0 0 0" xyz="0 0 0"/>
      <geometry name="rh_mounting_plate">
        <mesh filename="meshes/sr_hand/components/mounting_plate/mounting_plate_E3M5.dae" scale="0.001 0.001 0.001"/>
      </geometry>
    </visual>
    <collision>
      <origin rpy="0 0 0" xyz="0 0 0.002"/>
      <geometry>
        <cylinder length="0.008" radius="0.0675"/>
      </geometry>
    </collision>
    <!-- TODO: Make a decision on whether to add the connector or not -->
    <!--visual>
        <origin rpy="0 -1.57 -1.57" xyz="0.0 0.067 0.0045"/>
        <geometry name="${prefix}cable_extr_visualisation">
          <mesh filename="meshes/sr_hand/components/cable_connector/cable_connector_base_${hand_version}.dae" scale="0.001 0.001 0.001" />
        </geometry>
      </visual-->
  </link>
  <gazebo reference="rh_forearm">
    <selfCollide>false</selfCollide>
  </gazebo>
  <link name="rh_wrist">
    <inertial>
      <origin rpy="0 0 0" xyz="0 0 0.029"/>
      <mass value="0.1"/>
      <inertia ixx="0.000035" ixy="0.0" ixz="0.0" iyy="0.000064" iyz="0.0" izz="0.0000438"/>
    </inertial>
    <visual>
      <origin rpy="0 0 0" xyz="0 0 0"/>
      <geometry name="rh_wrist_visual">
        <mesh filename="meshes/sr_hand/components/wrist/wrist_E3M5.dae" scale="0.001 0.001 0.001"/>
      </geometry>
      <material name="LightGrey"/>
    </visual>
    <collision>
      <origin rpy="1.5708 1.5708 0" xyz="0 0 0"/>
      <geometry name="rh_wrist_collision_geom">
        <cylinder length="0.030" radius="0.0135"/>
      </geometry>
    </collision>
    <collision>
      <origin rpy="0 1.5708 0" xyz="-0.026 0 0.034"/>
      <geometry>
        <cylinder length="0.010" radius="0.011"/>
      </geometry>
    </collision>
    <collision>
      <origin rpy="0 1.5708 0" xyz="0.031 0 0.034"/>
      <geometry>
        <cylinder length="0.010" radius="0.011"/>
      </geometry>
    </collision>
    <collision>
      <origin rpy="0 0.7854 0" xyz="-0.021 0 0.011"/>
      <geometry>
        <box size="0.027 0.018 0.010"/>
      </geometry>
    </collision>
    <collision>
      <origin rpy="0 -0.7854 0" xyz="0.026 0 0.010"/>
      <geometry>
        <box size="0.027 0.018 0.010"/>
      </geometry>
    </collision>
  </link>
  <gazebo reference="rh_wrist">
    <material>Gazebo/White</material>
    <selfCollide>false</selfCollide>
  </gazebo>
  <joint name="rh_WRJ2" type="revolute">
    <parent link="rh_forearm"/>
    <child link="rh_wrist"/>
    <origin rpy="0 0 0" xyz="0 -0.010 0.21301"/>
    <axis xyz="0 1 0"/>
    <limit effort="10" lower="-0.5235987755982988" upper="0.17453292519943295" velocity="2.0"/>
    <dynamics damping="0.1"/>
  </joint>
  <gazebo reference="rh_WRJ2">
    <provideFeedback>1</provideFeedback>
    <implicitSpringDamper>1</implicitSpringDamper>
  </gazebo>
  <transmission name="rh_wrist_transmission">
    <type>sr_mechanism_model/SimpleTransmission</type>
    <actuator name="rh_WRJ2">
      <mechanicalReduction>1</mechanicalReduction>
    </actuator>
    <joint name="rh_WRJ2">
      <hardwareInterface>EffortJointInterface</hardwareInterface>
      <hardwareInterface>PositionJointInterface</hardwareInterface>
    </joint>
  </transmission>
  <link name="rh_palm">
    <inertial>
      <origin rpy="0 0 0" xyz="0 0 0.035"/>
      <mass value="0.3"/>
      <inertia ixx="0.0003581" ixy="0.0" ixz="0.0" iyy="0.0005287" iyz="0.0" izz="0.000191"/>
    </inertial>
    <visual>
      <origin rpy="0 0 0" xyz="0 0 0"/>
      <geometry name="rh_palm_visual">
        <mesh filename="meshes/sr_hand/components/palm/palm_E3M5.dae" scale="0.001 0.001 0.001"/>
      </geometry>
      <material name="Grey"/>
    </visual>
    <collision>
      <origin rpy="0 0 0" xyz="0.011 0.0085 0.038"/>
      <geometry name="rh_palm_collision_geom">
        <box size="0.062 0.007 0.098"/>
      </geometry>
    </collision>
    <collision>
      <origin rpy="0 0 0" xyz="-0.002 -0.0035 0.038"/>
      <geometry>
        <box size="0.036 0.017 0.098"/>
      </geometry>
    </collision>
    <!-- palm complement below first finger -->
    <collision>
      <origin rpy="0 0 0" xyz="0.029 -0.0035 0.082"/>
      <geometry>
        <box size="0.026 0.017 0.010"/>
      </geometry>
    </collision>
    <collision>
      <origin rpy="0.2 0 0.25" xyz="0.0265 -0.001 0.070"/>
      <geometry>
        <box size="0.026 0.014 0.018"/>
      </geometry>
    </collision>
    <!-- thumb pulp side -->
    <collision>
      <origin rpy="0 0 0" xyz="0.0315 -0.0085 0.001"/>
      <geometry>
        <box size="0.021 0.027 0.024"/>
      </geometry>
    </collision>
    <!-- thumb pulp central -->
    <collision>
      <origin rpy="0 0 -0.48" xyz="0.0125 -0.015 0.009"/>
      <geometry>
        <box size="0.022 0.005 0.040"/>
      </geometry>
    </collision>
    <!-- above middle finger-->
    <collision>
      <origin rpy="0 0 0" xyz="0.011 0 0.089"/>
      <geometry>
        <box size="0.018 0.024 0.004"/>
      </geometry>
    </collision>
    <!-- metacarpal side-->
    <collision>
      <origin rpy="0 0 0" xyz="-0.03 0 0.009"/>
      <geometry>
        <box size="0.020 0.024 0.040"/>
      </geometry>
    </collision>
  </link>
  <joint name="rh_ee_fixed_joint" type="fixed">
    <parent link="rh_palm"/>
    <child link="rh_manipulator"/>
    <origin rpy="0.0 0.0 0.0" xyz="0.0 0.0 0.05"/>
  </joint>
  <link name="rh_manipulator"/>
  <joint name="rh_WRJ1" type="revolute">
    <parent link="rh_wrist"/>
    <child link="rh_palm"/>
    <origin rpy="0 0 0" xyz="0 0 0.034"/>
    <axis xyz="1 0 0"/>
    <limit effort="30" lower="-0.6981317007977318" upper="0.4886921905584123" velocity="2.0"/>
    <dynamics damping="0.1"/>
  </joint>
  <gazebo reference="rh_WRJ1">
    <provideFeedback>1</provideFeedback>
    <implicitSpringDamper>1</implicitSpringDamper>
  </gazebo>
  <link name="rh_imu"/>
  <joint name="rh_palm_to_imu" type="fixed">
    <parent link="rh_palm"/>
    <child link="rh_imu"/>
    <origin rpy="-1.5707963 3.141592 0.0" xyz="0.01785 0.00765 0.049125"/>
  </joint>
  <transmission name="rh_palm_transmission">
    <type>sr_mechanism_model/SimpleTransmission</type>
    <actuator name="rh_WRJ1">
      <mechanicalReduction>1</mechanicalReduction>
    </actuator>
    <joint name="rh_WRJ1">
      <hardwareInterface>EffortJointInterface</hardwareInterface>
      <hardwareInterface>PositionJointInterface</hardwareInterface>
    </joint>
  </transmission>
  <gazebo reference="rh_palm">
  </gazebo>
  <link name="rh_ffknuckle">
    <inertial>
      <origin rpy="0 0 0" xyz="0 0 0"/>
      <mass value="0.008"/>
      <inertia ixx="0.00000026" ixy="0.0" ixz="0.0" iyy="0.00000026" iyz="0.0" izz="0.00000032"/>
    </inertial>
    <visual>
      <origin rpy="0 0 0" xyz="0 0 0.0005"/>
      <geometry name="rh_ffknuckle_visual">
        <mesh filename="meshes/sr_hand/components/f_knuckle/f_knuckle_E3M5.dae" scale="0.001 0.001 0.001"/>
      </geometry>
      <material name="LightGrey"/>
    </visual>
    <collision>
      <origin rpy="0 1.5708 0" xyz="0 0 0"/>
      <geometry name="rh_ffknuckle_collision_geom">
        <cylinder length="0.014" radius="0.007"/>
      </geometry>
    </collision>
  </link>
  <joint name="rh_FFJ4" type="revolute">
    <parent link="rh_palm"/>
    <child link="rh_ffknuckle"/>
    <!--<origin xyz="0.033 0 0.095" rpy="0 0 0" />-->
    <origin rpy="0 0 0" xyz="0.033 0 0.095"/>
    <axis xyz="0 -1 0"/>
    <limit effort="2" lower="-0.3490658503988659" upper="0.3490658503988659" velocity="2.0"/>
    <dynamics damping="0.1"/>
  </joint>
  <gazebo reference="rh_FFJ4">
    <provideFeedback>1</provideFeedback>
    <implicitSpringDamper>1</implicitSpringDamper>
  </gazebo>
  <transmission name="rh_ffknuckle_transmission">
    <type>sr_mechanism_model/SimpleTransmission</type>
    <actuator name="rh_FFJ4">
      <mechanicalReduction>1</mechanicalReduction>
    </actuator>
    <joint name="rh_FFJ4">
      <hardwareInterface>EffortJointInterface</hardwareInterface>
      <hardwareInterface>PositionJointInterface</hardwareInterface>
    </joint>
  </transmission>
  <gazebo reference="rh_ffknuckle">
    <!-- knuckle is not highly exposed, so bumper is not useful -->
    <material>Gazebo/Grey</material>
  </gazebo>
  <link name="rh_ffproximal">
    <inertial>
      <mass value="0.030"/>
      <origin xyz="0 0 0.0225"/>
      <inertia ixx="0.0000098" ixy="0.0" ixz="0.0" iyy="0.00001" iyz="0.0" izz="0.0000018"/>
    </inertial>
    <visual>
      <origin rpy="0 0 0" xyz="0 0 0"/>
      <geometry name="rh_ffproximal_visual">
        <mesh filename="meshes/sr_hand/components/f_proximal/f_proximal_E3M5.dae" scale="0.001 0.001 0.001"/>
      </geometry>
      <material name="Grey"/>
    </visual>
    <collision>
      <origin rpy="0 0 0" xyz="0 0 0.025"/>
      <geometry name="rh_ffproximal_collision_geom">
        <cylinder length="0.040" radius="0.007"/>
      </geometry>
    </collision>
  </link>
  <joint name="rh_FFJ3" type="revolute">
    <parent link="rh_ffknuckle"/>
    <child link="rh_ffproximal"/>
    <origin rpy="0 0 0" xyz="0 0 0"/>
    <axis xyz="1 0 0"/>
    <limit effort="2" lower="-0.2617993877991494" upper="1.5707963267948966" velocity="2.0"/>
    <dynamics damping="0.1"/>
  </joint>
  <gazebo reference="rh_FFJ3">
    <provideFeedback>1</provideFeedback>
    <implicitSpringDamper>1</implicitSpringDamper>
  </gazebo>
  <transmission name="rh_ffproximal_transmission">
    <type>sr_mechanism_model/SimpleTransmission</type>
    <actuator name="rh_FFJ3">
      <mechanicalReduction>1</mechanicalReduction>
    </actuator>
    <joint name="rh_FFJ3">
      <hardwareInterface>EffortJointInterface</hardwareInterface>
      <hardwareInterface>PositionJointInterface</hardwareInterface>
    </joint>
  </transmission>
  <gazebo reference="rh_ffproximal">
    <selfCollide>true</selfCollide>
  </gazebo>
  <link name="rh_ffmiddle">
    <inertial>
      <origin rpy="0 0 0" xyz="0 0 0.0125"/>
      <mass value="0.017"/>
      <inertia ixx="0.0000026" ixy="0.0" ixz="0.0" iyy="0.0000027" iyz="0.0" izz="0.00000087"/>
    </inertial>
    <visual>
      <origin rpy="0 0 0" xyz="0 0 0"/>
      <geometry name="rh_ffmiddle_visual">
        <mesh filename="meshes/sr_hand/components/f_middle/f_middle_E3M5.dae" scale="0.001 0.001 0.001"/>
      </geometry>
      <material name="Grey"/>
    </visual>
    <collision>
      <origin rpy="0 0 0" xyz="0 0 0.0125"/>
      <geometry name="rh_ffmiddle_collision_geom">
        <cylinder length="0.025" radius="0.007"/>
      </geometry>
    </collision>
    <collision>
      <origin rpy="0 0 0" xyz="0 0 0.0"/>
      <geometry>
        <sphere radius="0.007"/>
      </geometry>
    </collision>
    <collision>
      <origin rpy="0 0 0" xyz="0 0 0.025"/>
      <geometry>
        <sphere radius="0.007"/>
      </geometry>
    </collision>
  </link>
  <joint name="rh_FFJ2" type="revolute">
    <parent link="rh_ffproximal"/>
    <child link="rh_ffmiddle"/>
    <origin rpy="0 0 0" xyz="0 0 0.045"/>
    <axis xyz="1 0 0"/>
    <limit effort="2" lower="0" upper="1.5707963267948966" velocity="2.0"/>
    <dynamics damping="0.1"/>
  </joint>
  <gazebo reference="rh_FFJ2">
    <provideFeedback>1</provideFeedback>
    <implicitSpringDamper>1</implicitSpringDamper>
  </gazebo>
  <transmission name="rh_ffmiddle_transmission">
    <type>sr_mechanism_model/J0Transmission</type>
    <actuator name="rh_FFJ0">
      <mechanicalReduction>1</mechanicalReduction>
    </actuator>
    <joint name="rh_FFJ1">
      <hardwareInterface>EffortJointInterface</hardwareInterface>
      <hardwareInterface>PositionJointInterface</hardwareInterface>
    </joint>
  </transmission>
  <gazebo reference="rh_ffmiddle">
    <selfCollide>true</selfCollide>
  </gazebo>
  <link name="rh_ffdistal">
    <inertial>
      <mass value="0.012"/>
      <origin xyz="0 0 0.012"/>
      <inertia ixx="0.00000094" ixy="0.0" ixz="0.0" iyy="0.0000011" iyz="0.0" izz="0.00000053"/>
    </inertial>
    <visual>
      <origin rpy="0 0 0" xyz="0 0 0"/>
      <geometry name="rh_ffdistal_visual">
        <mesh filename="meshes/sr_hand/components/f_distal/pst/f_distal_pst.dae" scale="0.001 0.001 0.001"/>
      </geometry>
    </visual>
    <collision>
      <origin rpy="0 0 0" xyz="0 0 0"/>
      <geometry name="rh_ffdistal_collision_geom">
        <mesh filename="meshes/sr_hand/components/f_distal/pst/f_distal_pst.dae" scale="0.001 0.001 0.001"/>
      </geometry>
    </collision>
  </link>
  <joint name="rh_FFJ1" type="revolute">
    <parent link="rh_ffmiddle"/>
    <child link="rh_ffdistal"/>
    <origin rpy="0 0 0" xyz="0 0 0.025"/>
    <axis xyz="1 0 0"/>
    <!-- standard distal joint -->
    <limit effort="2" lower="0" upper="1.5707963267948966" velocity="2.0"/>
    <dynamics damping="0.1"/>
  </joint>
  <gazebo reference="rh_FFJ1">
    <provideFeedback>1</provideFeedback>
    <implicitSpringDamper>1</implicitSpringDamper>
  </gazebo>
  <link name="rh_fftip">
    <inertial>
      <mass value="0.001"/>
      <inertia ixx="0.0" ixy="0.0" ixz="0.0" iyy="0.0" iyz="0.0" izz="0.0"/>
    </inertial>
  </link>
  <joint name="rh_FFtip" type="fixed">
    <parent link="rh_ffdistal"/>
    <child link="rh_fftip"/>
    <origin rpy="0 0 0" xyz="0 0 0.026"/>
  </joint>
  <gazebo reference="rh_ffdistal">
    <sensor name="rh_ffdistal_contact" type="contact">
      <always_on>1</always_on>
      <update_rate>1000.0</update_rate>
      <contact>
        <collision>rh_ffdistal_collision</collision>
        <topic>rh_ffdistal_collision</topic>
      </contact>
      <plugin filename="libgazebo_ros_bumper.so" name="rh_ffdistal_gazebo_ros_bumper_controller">
        <alwaysOn>true</alwaysOn>
        <frameName>rh_ffdistal</frameName>
        <updateRate>100.0</updateRate>
        <bumperTopicName>contacts/rh_ff/distal</bumperTopicName>
      </plugin>
    </sensor>
    <mu1 value="500.0"/>
    <mu2 value="500.0"/>
    <kp value="10000000.0"/>
    <kd value="1.0"/>
    <selfCollide>true</selfCollide>
  </gazebo>
  <link name="rh_mfknuckle">
    <inertial>
      <origin rpy="0 0 0" xyz="0 0 0"/>
      <mass value="0.008"/>
      <inertia ixx="0.00000026" ixy="0.0" ixz="0.0" iyy="0.00000026" iyz="0.0" izz="0.00000032"/>
    </inertial>
    <visual>
      <origin rpy="0 0 0" xyz="0 0 0.0005"/>
      <geometry name="rh_mfknuckle_visual">
        <mesh filename="meshes/sr_hand/components/f_knuckle/f_knuckle_E3M5.dae" scale="0.001 0.001 0.001"/>
      </geometry>
      <material name="LightGrey"/>
    </visual>
    <collision>
      <origin rpy="0 1.5708 0" xyz="0 0 0"/>
      <geometry name="rh_mfknuckle_collision_geom">
        <cylinder length="0.014" radius="0.007"/>
      </geometry>
    </collision>
  </link>
  <joint name="rh_MFJ4" type="revolute">
    <parent link="rh_palm"/>
    <child link="rh_mfknuckle"/>
    <!--<origin xyz="0.033 0 0.095" rpy="0 0 0" />-->
    <origin rpy="0 0 0" xyz="0.011 0 0.099"/>
    <axis xyz="0 -1 0"/>
    <limit effort="2" lower="-0.3490658503988659" upper="0.3490658503988659" velocity="2.0"/>
    <dynamics damping="0.1"/>
  </joint>
  <gazebo reference="rh_MFJ4">
    <provideFeedback>1</provideFeedback>
    <implicitSpringDamper>1</implicitSpringDamper>
  </gazebo>
  <transmission name="rh_mfknuckle_transmission">
    <type>sr_mechanism_model/SimpleTransmission</type>
    <actuator name="rh_MFJ4">
      <mechanicalReduction>1</mechanicalReduction>
    </actuator>
    <joint name="rh_MFJ4">
      <hardwareInterface>EffortJointInterface</hardwareInterface>
      <hardwareInterface>PositionJointInterface</hardwareInterface>
    </joint>
  </transmission>
  <gazebo reference="rh_mfknuckle">
    <!-- knuckle is not highly exposed, so bumper is not useful -->
    <material>Gazebo/Grey</material>
  </gazebo>
  <link name="rh_mfproximal">
    <inertial>
      <mass value="0.030"/>
      <origin xyz="0 0 0.0225"/>
      <inertia ixx="0.0000098" ixy="0.0" ixz="0.0" iyy="0.00001" iyz="0.0" izz="0.0000018"/>
    </inertial>
    <visual>
      <origin rpy="0 0 0" xyz="0 0 0"/>
      <geometry name="rh_mfproximal_visual">
        <mesh filename="meshes/sr_hand/components/f_proximal/f_proximal_E3M5.dae" scale="0.001 0.001 0.001"/>
      </geometry>
      <material name="Grey"/>
    </visual>
    <collision>
      <origin rpy="0 0 0" xyz="0 0 0.025"/>
      <geometry name="rh_mfproximal_collision_geom">
        <cylinder length="0.040" radius="0.007"/>
      </geometry>
    </collision>
  </link>
  <joint name="rh_MFJ3" type="revolute">
    <parent link="rh_mfknuckle"/>
    <child link="rh_mfproximal"/>
    <origin rpy="0 0 0" xyz="0 0 0"/>
    <axis xyz="1 0 0"/>
    <limit effort="2" lower="-0.2617993877991494" upper="1.5707963267948966" velocity="2.0"/>
    <dynamics damping="0.1"/>
  </joint>
  <gazebo reference="rh_MFJ3">
    <provideFeedback>1</provideFeedback>
    <implicitSpringDamper>1</implicitSpringDamper>
  </gazebo>
  <transmission name="rh_mfproximal_transmission">
    <type>sr_mechanism_model/SimpleTransmission</type>
    <actuator name="rh_MFJ3">
      <mechanicalReduction>1</mechanicalReduction>
    </actuator>
    <joint name="rh_MFJ3">
      <hardwareInterface>EffortJointInterface</hardwareInterface>
      <hardwareInterface>PositionJointInterface</hardwareInterface>
    </joint>
  </transmission>
  <gazebo reference="rh_mfproximal">
    <selfCollide>true</selfCollide>
  </gazebo>
  <link name="rh_mfmiddle">
    <inertial>
      <origin rpy="0 0 0" xyz="0 0 0.0125"/>
      <mass value="0.017"/>
      <inertia ixx="0.0000026" ixy="0.0" ixz="0.0" iyy="0.0000027" iyz="0.0" izz="0.00000087"/>
    </inertial>
    <visual>
      <origin rpy="0 0 0" xyz="0 0 0"/>
      <geometry name="rh_mfmiddle_visual">
        <mesh filename="meshes/sr_hand/components/f_middle/f_middle_E3M5.dae" scale="0.001 0.001 0.001"/>
      </geometry>
      <material name="Grey"/>
    </visual>
    <collision>
      <origin rpy="0 0 0" xyz="0 0 0.0125"/>
      <geometry name="rh_mfmiddle_collision_geom">
        <cylinder length="0.025" radius="0.007"/>
      </geometry>
    </collision>
    <collision>
      <origin rpy="0 0 0" xyz="0 0 0.0"/>
      <geometry>
        <sphere radius="0.007"/>
      </geometry>
    </collision>
    <collision>
      <origin rpy="0 0 0" xyz="0 0 0.025"/>
      <geometry>
        <sphere radius="0.007"/>
      </geometry>
    </collision>
  </link>
  <joint name="rh_MFJ2" type="revolute">
    <parent link="rh_mfproximal"/>
    <child link="rh_mfmiddle"/>
    <origin rpy="0 0 0" xyz="0 0 0.045"/>
    <axis xyz="1 0 0"/>
    <limit effort="2" lower="0" upper="1.5707963267948966" velocity="2.0"/>
    <dynamics damping="0.1"/>
  </joint>
  <gazebo reference="rh_MFJ2">
    <provideFeedback>1</provideFeedback>
    <implicitSpringDamper>1</implicitSpringDamper>
  </gazebo>
  <transmission name="rh_mfmiddle_transmission">
    <type>sr_mechanism_model/J0Transmission</type>
    <actuator name="rh_MFJ0">
      <mechanicalReduction>1</mechanicalReduction>
    </actuator>
    <joint name="rh_MFJ1">
      <hardwareInterface>EffortJointInterface</hardwareInterface>
      <hardwareInterface>PositionJointInterface</hardwareInterface>
    </joint>
  </transmission>
  <gazebo reference="rh_mfmiddle">
    <selfCollide>true</selfCollide>
  </gazebo>
  <link name="rh_mfdistal">
    <inertial>
      <mass value="0.012"/>
      <origin xyz="0 0 0.012"/>
      <inertia ixx="0.00000094" ixy="0.0" ixz="0.0" iyy="0.0000011" iyz="0.0" izz="0.00000053"/>
    </inertial>
    <visual>
      <origin rpy="0 0 0" xyz="0 0 0"/>
      <geometry name="rh_mfdistal_visual">
        <mesh filename="meshes/sr_hand/components/f_distal/pst/f_distal_pst.dae" scale="0.001 0.001 0.001"/>
      </geometry>
    </visual>
    <collision>
      <origin rpy="0 0 0" xyz="0 0 0"/>
      <geometry name="rh_mfdistal_collision_geom">
        <mesh filename="meshes/sr_hand/components/f_distal/pst/f_distal_pst.dae" scale="0.001 0.001 0.001"/>
      </geometry>
    </collision>
  </link>
  <joint name="rh_MFJ1" type="revolute">
    <parent link="rh_mfmiddle"/>
    <child link="rh_mfdistal"/>
    <origin rpy="0 0 0" xyz="0 0 0.025"/>
    <axis xyz="1 0 0"/>
    <!-- standard distal joint -->
    <limit effort="2" lower="0" upper="1.5707963267948966" velocity="2.0"/>
    <dynamics damping="0.1"/>
  </joint>
  <gazebo reference="rh_MFJ1">
    <provideFeedback>1</provideFeedback>
    <implicitSpringDamper>1</implicitSpringDamper>
  </gazebo>
  <link name="rh_mftip">
    <inertial>
      <mass value="0.001"/>
      <inertia ixx="0.0" ixy="0.0" ixz="0.0" iyy="0.0" iyz="0.0" izz="0.0"/>
    </inertial>
  </link>
  <joint name="rh_MFtip" type="fixed">
    <parent link="rh_mfdistal"/>
    <child link="rh_mftip"/>
    <origin rpy="0 0 0" xyz="0 0 0.026"/>
  </joint>
  <gazebo reference="rh_mfdistal">
    <sensor name="rh_mfdistal_contact" type="contact">
      <always_on>1</always_on>
      <update_rate>1000.0</update_rate>
      <contact>
        <collision>rh_mfdistal_collision</collision>
        <topic>rh_mfdistal_collision</topic>
      </contact>
      <plugin filename="libgazebo_ros_bumper.so" name="rh_mfdistal_gazebo_ros_bumper_controller">
        <alwaysOn>true</alwaysOn>
        <frameName>rh_mfdistal</frameName>
        <updateRate>100.0</updateRate>
        <bumperTopicName>contacts/rh_mf/distal</bumperTopicName>
      </plugin>
    </sensor>
    <mu1 value="500.0"/>
    <mu2 value="500.0"/>
    <kp value="10000000.0"/>
    <kd value="1.0"/>
    <selfCollide>true</selfCollide>
  </gazebo>
  <link name="rh_rfknuckle">
    <inertial>
      <origin rpy="0 0 0" xyz="0 0 0"/>
      <mass value="0.008"/>
      <inertia ixx="0.00000026" ixy="0.0" ixz="0.0" iyy="0.00000026" iyz="0.0" izz="0.00000032"/>
    </inertial>
    <visual>
      <origin rpy="0 0 0" xyz="0 0 0.0005"/>
      <geometry name="rh_rfknuckle_visual">
        <mesh filename="meshes/sr_hand/components/f_knuckle/f_knuckle_E3M5.dae" scale="0.001 0.001 0.001"/>
      </geometry>
      <material name="LightGrey"/>
    </visual>
    <collision>
      <origin rpy="0 1.5708 0" xyz="0 0 0"/>
      <geometry name="rh_rfknuckle_collision_geom">
        <cylinder length="0.014" radius="0.007"/>
      </geometry>
    </collision>
  </link>
  <joint name="rh_RFJ4" type="revolute">
    <parent link="rh_palm"/>
    <child link="rh_rfknuckle"/>
    <!--<origin xyz="0.033 0 0.095" rpy="0 0 0" />-->
    <origin rpy="0 0 0" xyz="-0.011 0 0.095"/>
    <axis xyz="0 1 0"/>
    <limit effort="2" lower="-0.3490658503988659" upper="0.3490658503988659" velocity="2.0"/>
    <dynamics damping="0.1"/>
  </joint>
  <gazebo reference="rh_RFJ4">
    <provideFeedback>1</provideFeedback>
    <implicitSpringDamper>1</implicitSpringDamper>
  </gazebo>
  <transmission name="rh_rfknuckle_transmission">
    <type>sr_mechanism_model/SimpleTransmission</type>
    <actuator name="rh_RFJ4">
      <mechanicalReduction>1</mechanicalReduction>
    </actuator>
    <joint name="rh_RFJ4">
      <hardwareInterface>EffortJointInterface</hardwareInterface>
      <hardwareInterface>PositionJointInterface</hardwareInterface>
    </joint>
  </transmission>
  <gazebo reference="rh_rfknuckle">
    <!-- knuckle is not highly exposed, so bumper is not useful -->
    <material>Gazebo/Grey</material>
  </gazebo>
  <link name="rh_rfproximal">
    <inertial>
      <mass value="0.030"/>
      <origin xyz="0 0 0.0225"/>
      <inertia ixx="0.0000098" ixy="0.0" ixz="0.0" iyy="0.00001" iyz="0.0" izz="0.0000018"/>
    </inertial>
    <visual>
      <origin rpy="0 0 0" xyz="0 0 0"/>
      <geometry name="rh_rfproximal_visual">
        <mesh filename="meshes/sr_hand/components/f_proximal/f_proximal_E3M5.dae" scale="0.001 0.001 0.001"/>
      </geometry>
      <material name="Grey"/>
    </visual>
    <collision>
      <origin rpy="0 0 0" xyz="0 0 0.025"/>
      <geometry name="rh_rfproximal_collision_geom">
        <cylinder length="0.040" radius="0.007"/>
      </geometry>
    </collision>
  </link>
  <joint name="rh_RFJ3" type="revolute">
    <parent link="rh_rfknuckle"/>
    <child link="rh_rfproximal"/>
    <origin rpy="0 0 0" xyz="0 0 0"/>
    <axis xyz="1 0 0"/>
    <limit effort="2" lower="-0.2617993877991494" upper="1.5707963267948966" velocity="2.0"/>
    <dynamics damping="0.1"/>
  </joint>
  <gazebo reference="rh_RFJ3">
    <provideFeedback>1</provideFeedback>
    <implicitSpringDamper>1</implicitSpringDamper>
  </gazebo>
  <transmission name="rh_rfproximal_transmission">
    <type>sr_mechanism_model/SimpleTransmission</type>
    <actuator name="rh_RFJ3">
      <mechanicalReduction>1</mechanicalReduction>
    </actuator>
    <joint name="rh_RFJ3">
      <hardwareInterface>EffortJointInterface</hardwareInterface>
      <hardwareInterface>PositionJointInterface</hardwareInterface>
    </joint>
  </transmission>
  <gazebo reference="rh_rfproximal">
    <selfCollide>true</selfCollide>
  </gazebo>
  <link name="rh_rfmiddle">
    <inertial>
      <origin rpy="0 0 0" xyz="0 0 0.0125"/>
      <mass value="0.017"/>
      <inertia ixx="0.0000026" ixy="0.0" ixz="0.0" iyy="0.0000027" iyz="0.0" izz="0.00000087"/>
    </inertial>
    <visual>
      <origin rpy="0 0 0" xyz="0 0 0"/>
      <geometry name="rh_rfmiddle_visual">
        <mesh filename="meshes/sr_hand/components/f_middle/f_middle_E3M5.dae" scale="0.001 0.001 0.001"/>
      </geometry>
      <material name="Grey"/>
    </visual>
    <collision>
      <origin rpy="0 0 0" xyz="0 0 0.0125"/>
      <geometry name="rh_rfmiddle_collision_geom">
        <cylinder length="0.025" radius="0.007"/>
      </geometry>
    </collision>
    <collision>
      <origin rpy="0 0 0" xyz="0 0 0.0"/>
      <geometry>
        <sphere radius="0.007"/>
      </geometry>
    </collision>
    <collision>
      <origin rpy="0 0 0" xyz="0 0 0.025"/>
      <geometry>
        <sphere radius="0.007"/>
      </geometry>
    </collision>
  </link>
  <joint name="rh_RFJ2" type="revolute">
    <parent link="rh_rfproximal"/>
    <child link="rh_rfmiddle"/>
    <origin rpy="0 0 0" xyz="0 0 0.045"/>
    <axis xyz="1 0 0"/>
    <limit effort="2" lower="0" upper="1.5707963267948966" velocity="2.0"/>
    <dynamics damping="0.1"/>
  </joint>
  <gazebo reference="rh_RFJ2">
    <provideFeedback>1</provideFeedback>
    <implicitSpringDamper>1</implicitSpringDamper>
  </gazebo>
  <transmission name="rh_rfmiddle_transmission">
    <type>sr_mechanism_model/J0Transmission</type>
    <actuator name="rh_RFJ0">
      <mechanicalReduction>1</mechanicalReduction>
    </actuator>
    <joint name="rh_RFJ1">
      <hardwareInterface>EffortJointInterface</hardwareInterface>
      <hardwareInterface>PositionJointInterface</hardwareInterface>
    </joint>
  </transmission>
  <gazebo reference="rh_rfmiddle">
    <selfCollide>true</selfCollide>
  </gazebo>
  <link name="rh_rfdistal">
    <inertial>
      <mass value="0.012"/>
      <origin xyz="0 0 0.012"/>
      <inertia ixx="0.00000094" ixy="0.0" ixz="0.0" iyy="0.0000011" iyz="0.0" izz="0.00000053"/>
    </inertial>
    <visual>
      <origin rpy="0 0 0" xyz="0 0 0"/>
      <geometry name="rh_rfdistal_visual">
        <mesh filename="meshes/sr_hand/components/f_distal/pst/f_distal_pst.dae" scale="0.001 0.001 0.001"/>
      </geometry>
    </visual>
    <collision>
      <origin rpy="0 0 0" xyz="0 0 0"/>
      <geometry name="rh_rfdistal_collision_geom">
        <mesh filename="meshes/sr_hand/components/f_distal/pst/f_distal_pst.dae" scale="0.001 0.001 0.001"/>
      </geometry>
    </collision>
  </link>
  <joint name="rh_RFJ1" type="revolute">
    <parent link="rh_rfmiddle"/>
    <child link="rh_rfdistal"/>
    <origin rpy="0 0 0" xyz="0 0 0.025"/>
    <axis xyz="1 0 0"/>
    <!-- standard distal joint -->
    <limit effort="2" lower="0" upper="1.5707963267948966" velocity="2.0"/>
    <dynamics damping="0.1"/>
  </joint>
  <gazebo reference="rh_RFJ1">
    <provideFeedback>1</provideFeedback>
    <implicitSpringDamper>1</implicitSpringDamper>
  </gazebo>
  <link name="rh_rftip">
    <inertial>
      <mass value="0.001"/>
      <inertia ixx="0.0" ixy="0.0" ixz="0.0" iyy="0.0" iyz="0.0" izz="0.0"/>
    </inertial>
  </link>
  <joint name="rh_RFtip" type="fixed">
    <parent link="rh_rfdistal"/>
    <child link="rh_rftip"/>
    <origin rpy="0 0 0" xyz="0 0 0.026"/>
  </joint>
  <gazebo reference="rh_rfdistal">
    <sensor name="rh_rfdistal_contact" type="contact">
      <always_on>1</always_on>
      <update_rate>1000.0</update_rate>
      <contact>
        <collision>rh_rfdistal_collision</collision>
        <topic>rh_rfdistal_collision</topic>
      </contact>
      <plugin filename="libgazebo_ros_bumper.so" name="rh_rfdistal_gazebo_ros_bumper_controller">
        <alwaysOn>true</alwaysOn>
        <frameName>rh_rfdistal</frameName>
        <updateRate>100.0</updateRate>
        <bumperTopicName>contacts/rh_rf/distal</bumperTopicName>
      </plugin>
    </sensor>
    <mu1 value="500.0"/>
    <mu2 value="500.0"/>
    <kp value="10000000.0"/>
    <kd value="1.0"/>
    <selfCollide>true</selfCollide>
  </gazebo>
  <link name="rh_lfmetacarpal">
    <inertial>
      <origin rpy="0 0 0" xyz="0 0 0.04"/>
      <mass value="0.030"/>
      <inertia ixx="0.0000145" ixy="0.0" ixz="0.0" iyy="0.00001638" iyz="0.0" izz="0.000004272"/>
    </inertial>
    <visual>
      <origin rpy="0 0.9599 0" xyz="0 0 0"/>
      <geometry name="rh_lfmetacarpal_visual">
        <mesh filename="meshes/sr_hand/components/lf_metacarpal/lf_metacarpal_E3M5.dae" scale="0.001 0.001 0.001"/>
      </geometry>
      <material name="Grey"/>
    </visual>
    <collision>
      <origin rpy="0 0.9599 0" xyz="0.026986375 0 0.019"/>
      <geometry name="rh_lfmetacarpal_collision_geom">
        <box size="0.018 0.024 0.040"/>
      </geometry>
    </collision>
  </link>
  <joint name="rh_LFJ5" type="revolute">
    <parent link="rh_palm"/>
    <child link="rh_lfmetacarpal"/>
    <origin rpy="0 -0.9599 0" xyz="-0.033 0 0.02071"/>
    <axis xyz="1 0 0"/>
    <limit effort="2" lower="0" upper="0.7853981633974483" velocity="2.0"/>
    <dynamics damping="0.1"/>
  </joint>
  <gazebo reference="rh_LFJ5">
    <provideFeedback>1</provideFeedback>
    <implicitSpringDamper>1</implicitSpringDamper>
  </gazebo>
  <transmission name="rh_lfmetacarpal_transmission">
    <type>sr_mechanism_model/SimpleTransmission</type>
    <actuator name="rh_LFJ5">
      <mechanicalReduction>1</mechanicalReduction>
    </actuator>
    <joint name="rh_LFJ5">
      <hardwareInterface>EffortJointInterface</hardwareInterface>
      <hardwareInterface>PositionJointInterface</hardwareInterface>
    </joint>
  </transmission>
  <gazebo reference="rh_lfmetacarpal">
    <selfCollide>true</selfCollide>
  </gazebo>
  <link name="rh_lfknuckle">
    <inertial>
      <origin rpy="0 0 0" xyz="0 0 0"/>
      <mass value="0.008"/>
      <inertia ixx="0.00000026" ixy="0.0" ixz="0.0" iyy="0.00000026" iyz="0.0" izz="0.00000032"/>
    </inertial>
    <visual>
      <origin rpy="0 0 0" xyz="0 0 0.0005"/>
      <geometry name="rh_lfknuckle_visual">
        <mesh filename="meshes/sr_hand/components/f_knuckle/f_knuckle_E3M5.dae" scale="0.001 0.001 0.001"/>
      </geometry>
      <material name="LightGrey"/>
    </visual>
    <collision>
      <origin rpy="0 1.5708 0" xyz="0 0 0"/>
      <geometry name="rh_lfknuckle_collision_geom">
        <cylinder length="0.014" radius="0.007"/>
      </geometry>
    </collision>
  </link>
  <joint name="rh_LFJ4" type="revolute">
    <parent link="rh_lfmetacarpal"/>
    <child link="rh_lfknuckle"/>
    <!--<origin xyz="0.033 0 0.095" rpy="0 0 0" />-->
    <origin rpy="0 0.9599 0" xyz="0.05397275 0 0.03779463"/>
    <axis xyz="0 1 0"/>
    <limit effort="2" lower="-0.3490658503988659" upper="0.3490658503988659" velocity="2.0"/>
    <dynamics damping="0.1"/>
  </joint>
  <gazebo reference="rh_LFJ4">
    <provideFeedback>1</provideFeedback>
    <implicitSpringDamper>1</implicitSpringDamper>
  </gazebo>
  <transmission name="rh_lfknuckle_transmission">
    <type>sr_mechanism_model/SimpleTransmission</type>
    <actuator name="rh_LFJ4">
      <mechanicalReduction>1</mechanicalReduction>
    </actuator>
    <joint name="rh_LFJ4">
      <hardwareInterface>EffortJointInterface</hardwareInterface>
      <hardwareInterface>PositionJointInterface</hardwareInterface>
    </joint>
  </transmission>
  <gazebo reference="rh_lfknuckle">
    <!-- knuckle is not highly exposed, so bumper is not useful -->
    <material>Gazebo/Grey</material>
  </gazebo>
  <link name="rh_lfproximal">
    <inertial>
      <mass value="0.030"/>
      <origin xyz="0 0 0.0225"/>
      <inertia ixx="0.0000098" ixy="0.0" ixz="0.0" iyy="0.00001" iyz="0.0" izz="0.0000018"/>
    </inertial>
    <visual>
      <origin rpy="0 0 0" xyz="0 0 0"/>
      <geometry name="rh_lfproximal_visual">
        <mesh filename="meshes/sr_hand/components/f_proximal/f_proximal_E3M5.dae" scale="0.001 0.001 0.001"/>
      </geometry>
      <material name="Grey"/>
    </visual>
    <collision>
      <origin rpy="0 0 0" xyz="0 0 0.025"/>
      <geometry name="rh_lfproximal_collision_geom">
        <cylinder length="0.040" radius="0.007"/>
      </geometry>
    </collision>
  </link>
  <joint name="rh_LFJ3" type="revolute">
    <parent link="rh_lfknuckle"/>
    <child link="rh_lfproximal"/>
    <origin rpy="0 0 0" xyz="0 0 0"/>
    <axis xyz="1 0 0"/>
    <limit effort="2" lower="-0.2617993877991494" upper="1.5707963267948966" velocity="2.0"/>
    <dynamics damping="0.1"/>
  </joint>
  <gazebo reference="rh_LFJ3">
    <provideFeedback>1</provideFeedback>
    <implicitSpringDamper>1</implicitSpringDamper>
  </gazebo>
  <transmission name="rh_lfproximal_transmission">
    <type>sr_mechanism_model/SimpleTransmission</type>
    <actuator name="rh_LFJ3">
      <mechanicalReduction>1</mechanicalReduction>
    </actuator>
    <joint name="rh_LFJ3">
      <hardwareInterface>EffortJointInterface</hardwareInterface>
      <hardwareInterface>PositionJointInterface</hardwareInterface>
    </joint>
  </transmission>
  <gazebo reference="rh_lfproximal">
    <selfCollide>true</selfCollide>
  </gazebo>
  <link name="rh_lfmiddle">
    <inertial>
      <origin rpy="0 0 0" xyz="0 0 0.0125"/>
      <mass value="0.017"/>
      <inertia ixx="0.0000026" ixy="0.0" ixz="0.0" iyy="0.0000027" iyz="0.0" izz="0.00000087"/>
    </inertial>
    <visual>
      <origin rpy="0 0 0" xyz="0 0 0"/>
      <geometry name="rh_lfmiddle_visual">
        <mesh filename="meshes/sr_hand/components/f_middle/f_middle_E3M5.dae" scale="0.001 0.001 0.001"/>
      </geometry>
      <material name="Grey"/>
    </visual>
    <collision>
      <origin rpy="0 0 0" xyz="0 0 0.0125"/>
      <geometry name="rh_lfmiddle_collision_geom">
        <cylinder length="0.025" radius="0.007"/>
      </geometry>
    </collision>
    <collision>
      <origin rpy="0 0 0" xyz="0 0 0.0"/>
      <geometry>
        <sphere radius="0.007"/>
      </geometry>
    </collision>
    <collision>
      <origin rpy="0 0 0" xyz="0 0 0.025"/>
      <geometry>
        <sphere radius="0.007"/>
      </geometry>
    </collision>
  </link>
  <joint name="rh_LFJ2" type="revolute">
    <parent link="rh_lfproximal"/>
    <child link="rh_lfmiddle"/>
    <origin rpy="0 0 0" xyz="0 0 0.045"/>
    <axis xyz="1 0 0"/>
    <limit effort="2" lower="0" upper="1.5707963267948966" velocity="2.0"/>
    <dynamics damping="0.1"/>
  </joint>
  <gazebo reference="rh_LFJ2">
    <provideFeedback>1</provideFeedback>
    <implicitSpringDamper>1</implicitSpringDamper>
  </gazebo>
  <transmission name="rh_lfmiddle_transmission">
    <type>sr_mechanism_model/J0Transmission</type>
    <actuator name="rh_LFJ0">
      <mechanicalReduction>1</mechanicalReduction>
    </actuator>
    <joint name="rh_LFJ1">
      <hardwareInterface>EffortJointInterface</hardwareInterface>
      <hardwareInterface>PositionJointInterface</hardwareInterface>
    </joint>
  </transmission>
  <gazebo reference="rh_lfmiddle">
    <selfCollide>true</selfCollide>
  </gazebo>
  <link name="rh_lfdistal">
    <inertial>
      <mass value="0.012"/>
      <origin xyz="0 0 0.012"/>
      <inertia ixx="0.00000094" ixy="0.0" ixz="0.0" iyy="0.0000011" iyz="0.0" izz="0.00000053"/>
    </inertial>
    <visual>
      <origin rpy="0 0 0" xyz="0 0 0"/>
      <geometry name="rh_lfdistal_visual">
        <mesh filename="meshes/sr_hand/components/f_distal/pst/f_distal_pst.dae" scale="0.001 0.001 0.001"/>
      </geometry>
    </visual>
    <collision>
      <origin rpy="0 0 0" xyz="0 0 0"/>
      <geometry name="rh_lfdistal_collision_geom">
        <mesh filename="meshes/sr_hand/components/f_distal/pst/f_distal_pst.dae" scale="0.001 0.001 0.001"/>
      </geometry>
    </collision>
  </link>
  <joint name="rh_LFJ1" type="revolute">
    <parent link="rh_lfmiddle"/>
    <child link="rh_lfdistal"/>
    <origin rpy="0 0 0" xyz="0 0 0.025"/>
    <axis xyz="1 0 0"/>
    <!-- standard distal joint -->
    <limit effort="2" lower="0" upper="1.5707963267948966" velocity="2.0"/>
    <dynamics damping="0.1"/>
  </joint>
  <gazebo reference="rh_LFJ1">
    <provideFeedback>1</provideFeedback>
    <implicitSpringDamper>1</implicitSpringDamper>
  </gazebo>
  <link name="rh_lftip">
    <inertial>
      <mass value="0.001"/>
      <inertia ixx="0.0" ixy="0.0" ixz="0.0" iyy="0.0" iyz="0.0" izz="0.0"/>
    </inertial>
  </link>
  <joint name="rh_LFtip" type="fixed">
    <parent link="rh_lfdistal"/>
    <child link="rh_lftip"/>
    <origin rpy="0 0 0" xyz="0 0 0.026"/>
  </joint>
  <gazebo reference="rh_lfdistal">
    <sensor name="rh_lfdistal_contact" type="contact">
      <always_on>1</always_on>
      <update_rate>1000.0</update_rate>
      <contact>
        <collision>rh_lfdistal_collision</collision>
        <topic>rh_lfdistal_collision</topic>
      </contact>
      <plugin filename="libgazebo_ros_bumper.so" name="rh_lfdistal_gazebo_ros_bumper_controller">
        <alwaysOn>true</alwaysOn>
        <frameName>rh_lfdistal</frameName>
        <updateRate>100.0</updateRate>
        <bumperTopicName>contacts/rh_lf/distal</bumperTopicName>
      </plugin>
    </sensor>
    <mu1 value="500.0"/>
    <mu2 value="500.0"/>
    <kp value="10000000.0"/>
    <kd value="1.0"/>
    <selfCollide>true</selfCollide>
  </gazebo>
  <link name="rh_thbase">
    <inertial>
      <mass value="0.010"/>
      <origin rpy="0 0 0" xyz="0 0 0"/>
      <inertia ixx="0.00000016" ixy="0.0" ixz="0.0" iyy="0.00000016" iyz="0.0" izz="0.00000016"/>
    </inertial>
    <visual>
      <origin rpy="0 0 0" xyz="0 0 0"/>
      <geometry name="rh_thbase_visual">
        <box size="0.001 0.001 0.001"/>
      </geometry>
      <material name="shadow_thbase_material">
        <color rgba="0.5 0.5 0.5 1.0"/>
      </material>
    </visual>
    <collision>
      <origin rpy="0 0 0" xyz="0 0 0"/>
      <geometry name="rh_thbase_collision_geom">
        <sphere radius="0.011"/>
      </geometry>
    </collision>
  </link>
  <joint name="rh_THJ5" type="revolute">
    <parent link="rh_palm"/>
    <child link="rh_thbase"/>
    <origin rpy="-0.7853981633974483 0 -1.5707963267948966" xyz="0.034 -0.00858 0.029"/>
    <axis xyz="0 0 -1"/>
    <limit effort="5.0" lower="-1.0471975511965976" upper="1.0471975511965976" velocity="4.0"/>
    <dynamics damping="0.2"/>
  </joint>
  <gazebo reference="rh_THJ5">
    <provideFeedback>1</provideFeedback>
    <implicitSpringDamper>1</implicitSpringDamper>
  </gazebo>
  <transmission name="rh_thbase_transmission">
    <type>sr_mechanism_model/SimpleTransmission</type>
    <actuator name="rh_THJ5">
      <mechanicalReduction>1</mechanicalReduction>
    </actuator>
    <joint name="rh_THJ5">
      <hardwareInterface>EffortJointInterface</hardwareInterface>
      <hardwareInterface>PositionJointInterface</hardwareInterface>
    </joint>
  </transmission>
  <gazebo reference="rh_thbase">
    <!-- base is inside the proximal and not exposed, so bumper is not needed -->
    <selfCollide>false</selfCollide>
  </gazebo>
  <link name="rh_thproximal">
    <inertial>
      <mass value="0.040"/>
      <origin rpy="0 0 0" xyz="0 0 0.019"/>
      <inertia ixx="0.0000136" ixy="0.0" ixz="0.0" iyy="0.0000136" iyz="0.0" izz="0.00000313"/>
    </inertial>
    <visual>
      <origin rpy="0 0 0" xyz="0 0 0"/>
      <geometry name="rh_thproximal_visual">
        <mesh filename="meshes/sr_hand/components/th_proximal/th_proximal_E3M5.dae" scale="0.001 0.001 0.001"/>
      </geometry>
      <material name="shadow_thproximal_material">
        <color rgba="0.2 0.2 0.2 1.0"/>
      </material>
    </visual>
    <collision>
      <origin rpy="0 0 0" xyz="0 0 0.020"/>
      <geometry name="rh_thproximal_collision_geom">
        <cylinder length="0.018" radius="0.012"/>
      </geometry>
    </collision>
  </link>
  <joint name="rh_THJ4" type="revolute">
    <parent link="rh_thbase"/>
    <child link="rh_thproximal"/>
    <origin rpy="0 0 0" xyz="0 0 0"/>
    <axis xyz="0 1 0"/>
    <limit effort="3" lower="0.0" upper="1.2217304763960306" velocity="4.0"/>
    <dynamics damping="0.2"/>
  </joint>
  <gazebo reference="rh_THJ4">
    <provideFeedback>1</provideFeedback>
    <implicitSpringDamper>1</implicitSpringDamper>
  </gazebo>
  <transmission name="rh_thproximal_transmission">
    <type>sr_mechanism_model/SimpleTransmission</type>
    <actuator name="rh_THJ4">
      <mechanicalReduction>1</mechanicalReduction>
    </actuator>
    <joint name="rh_THJ4">
      <hardwareInterface>EffortJointInterface</hardwareInterface>
      <hardwareInterface>PositionJointInterface</hardwareInterface>
    </joint>
  </transmission>
  <gazebo reference="rh_thproximal">
    <selfCollide>false</selfCollide>
  </gazebo>
  <link name="rh_thhub">
    <inertial>
      <mass value="0.005"/>
      <origin rpy="0 0 0" xyz="0 0 0"/>
      <inertia ixx="0.000001" ixy="0.0" ixz="0.0" iyy="0.000001" iyz="0.0" izz="0.0000003"/>
    </inertial>
    <visual>
      <origin rpy="0 0 0" xyz="0 0 0"/>
      <geometry name="rh_thhub_visual">
        <box size="0.001 0.001 0.001"/>
      </geometry>
      <material name="shadow_thhub_material">
        <color rgba="0.7 0.7 0.7 1.0"/>
      </material>
    </visual>
    <collision>
      <origin rpy="0 0 0" xyz="0 0 0"/>
      <geometry name="rh_thhub_collision_geom">
        <sphere radius="0.010"/>
      </geometry>
    </collision>
  </link>
  <joint name="rh_THJ3" type="revolute">
    <parent link="rh_thproximal"/>
    <child link="rh_thhub"/>
    <origin rpy="0 0 0" xyz="0 0 0.038"/>
    <axis xyz="0 1 0"/>
    <limit effort="2.0" lower="-0.20943951023931953" upper="0.20943951023931953" velocity="4.0"/>
    <dynamics damping="0.2"/>
  </joint>
  <gazebo reference="rh_THJ3">
    <provideFeedback>1</provideFeedback>
    <implicitSpringDamper>1</implicitSpringDamper>
  </gazebo>
  <transmission name="rh_thhub_transmission">
    <type>sr_mechanism_model/SimpleTransmission</type>
    <actuator name="rh_THJ3">
      <mechanicalReduction>1</mechanicalReduction>
    </actuator>
    <joint name="rh_THJ3">
      <hardwareInterface>EffortJointInterface</hardwareInterface>
      <hardwareInterface>PositionJointInterface</hardwareInterface>
    </joint>
  </transmission>
  <gazebo reference="rh_thhub">
    <!-- hub is inside the proximal and not exposed, so bumper is not needed -->
    <selfCollide>false</selfCollide>
  </gazebo>
  <link name="rh_thmiddle">
    <inertial>
      <mass value="0.020"/>
      <origin rpy="0 0 0" xyz="0 0 0.016"/>
      <inertia ixx="0.0000051" ixy="0.0" ixz="0.0" iyy="0.0000051" iyz="0.0" izz="0.00000121"/>
    </inertial>
    <visual>
      <origin rpy="0 0 0" xyz="0 0 0"/>
      <geometry name="rh_thmiddle_visual">
        <mesh filename="meshes/sr_hand/components/th_middle/th_middle_E3M5.dae" scale="0.001 0.001 0.001"/>
      </geometry>
      <material name="shadow_thmiddle_material">
        <color rgba="0.2 0.2 0.2 1.0"/>
      </material>
    </visual>
    <collision>
      <origin rpy="0 0 0" xyz="0 0 0.012"/>
      <geometry name="rh_thmiddle_collision_geom">
        <cylinder length="0.018" radius="0.011"/>
      </geometry>
    </collision>
    <collision>
      <origin rpy="0 0 0" xyz="0 0 0.019"/>
      <geometry>
        <sphere radius="0.011"/>
      </geometry>
    </collision>
    <collision>
      <origin rpy="0 1.5708 0" xyz="0 0 0.032"/>
      <geometry>
        <cylinder length="0.014" radius="0.010"/>
      </geometry>
    </collision>
  </link>
  <joint name="rh_THJ2" type="revolute">
    <parent link="rh_thhub"/>
    <child link="rh_thmiddle"/>
    <origin rpy="0 0 0" xyz="0 0 0"/>
    <axis xyz="1 0 0"/>
    <limit effort="2.0" lower="-0.6981317007977318" upper="0.6981317007977318" velocity="2.0"/>
    <dynamics damping="0.1"/>
  </joint>
  <gazebo reference="rh_THJ2">
    <provideFeedback>1</provideFeedback>
    <implicitSpringDamper>1</implicitSpringDamper>
  </gazebo>
  <transmission name="rh_thmiddle_transmission">
    <type>sr_mechanism_model/SimpleTransmission</type>
    <actuator name="rh_THJ2">
      <mechanicalReduction>1</mechanicalReduction>
    </actuator>
    <joint name="rh_THJ2">
      <hardwareInterface>EffortJointInterface</hardwareInterface>
      <hardwareInterface>PositionJointInterface</hardwareInterface>
    </joint>
  </transmission>
  <gazebo reference="rh_thmiddle">
  </gazebo>
  <!-- common -->
  <link name="rh_thdistal">
    <inertial>
      <mass value="0.016"/>
      <origin rpy="0 0 0" xyz="0 0 0.01375"/>
      <inertia ixx="0.0000021" ixy="0.0" ixz="0.0" iyy="0.0000022" iyz="0.0" izz="0.000001"/>
    </inertial>
    <visual>
      <origin rpy="0 0 0" xyz="0 0 0"/>
      <geometry name="rh_thdistal_visual">
        <mesh filename="meshes/sr_hand/components/th_distal/pst/th_distal_pst.dae" scale="0.001 0.001 0.001"/>
      </geometry>
      <material name="shadow_thmiddle_material">
        <color rgba="0.2 0.2 0.2 1.0"/>
      </material>
    </visual>
    <collision>
      <origin rpy="0 0 0" xyz="0 0 0"/>
      <geometry name="rh_thmiddle_collision_geom">
        <mesh filename="meshes/sr_hand/components/th_distal/pst/th_distal_pst.dae" scale="0.001 0.001 0.001"/>
      </geometry>
    </collision>
  </link>
  <joint name="rh_THJ1" type="revolute">
    <parent link="rh_thmiddle"/>
    <child link="rh_thdistal"/>
    <origin rpy="0 0 0" xyz="0 0 0.032"/>
    <axis xyz="1 0 0"/>
    <limit effort="1.0" lower="-0.2617993877991494" upper="1.5707963267948966" velocity="4.0"/>
    <dynamics damping="0.2"/>
  </joint>
  <gazebo reference="rh_THJ1">
    <provideFeedback>1</provideFeedback>
    <implicitSpringDamper>1</implicitSpringDamper>
  </gazebo>
  <link name="rh_thtip">
    <inertial>
      <mass value="0.001"/>
      <inertia ixx="0.0" ixy="0.0" ixz="0.0" iyy="0.0" iyz="0.0" izz="0.0"/>
    </inertial>
  </link>
  <joint name="rh_thtip" type="fixed">
    <parent link="rh_thdistal"/>
    <child link="rh_thtip"/>
    <origin rpy="0 0 0" xyz="0 0 0.0275"/>
  </joint>
  <gazebo reference="rh_thdistal">
    <sensor name="rh_thdistal_contact" type="contact">
      <always_on>1</always_on>
      <update_rate>1000.0</update_rate>
      <contact>
        <collision>rh_thdistal_collision</collision>
        <topic>rh_thdistal_collision</topic>
      </contact>
      <plugin filename="libgazebo_ros_bumper.so" name="rh_thdistal_gazebo_ros_bumper_controller">
        <alwaysOn>true</alwaysOn>
        <frameName>rh_thdistal</frameName>
        <updateRate>100.0</updateRate>
        <bumperTopicName>contacts/rh_th/distal</bumperTopicName>
      </plugin>
    </sensor>
    <mu1 value="500.0"/>
    <mu2 value="500.0"/>
    <kp value="10000000.0"/>
    <kd value="1.0"/>
    <selfCollide>true</selfCollide>
  </gazebo>
  <transmission name="rh_thdistal_transmission">
    <type>sr_mechanism_model/SimpleTransmission</type>
    <actuator name="rh_THJ1">
      <mechanicalReduction>1</mechanicalReduction>
    </actuator>
    <joint name="rh_THJ1">
      <hardwareInterface>EffortJointInterface</hardwareInterface>
      <hardwareInterface>PositionJointInterface</hardwareInterface>
    </joint>
  </transmission>
  <joint name="world_joint" type="fixed">
    <parent link="world"/>
    <child link="ra_base_link"/>
    <origin rpy="0.0 0.0 0.0" xyz="0.0 0.0 0.0"/>
  </joint>
  <joint name="ra_arm_to_hand" type="fixed">
    <parent link="ra_flange"/>
    <child link="rh_forearm"/>
    <origin rpy="1.5707963267948966 3.141592653589793 1.5707963267948966" xyz="0.0 0.0 0.0"/>
  </joint>
</robot>
